<?xml version="1.0" ?>
<mujoco model="gen3_robotiq_2f_85">
    <compiler angle="radian" meshdir="gen3/"/>
    <option cone="elliptic"/>
    <size njmax="500" nconmax="500"/>
    <visual>
        <global offwidth="2488" offheight="1376"/>
    </visual>
    <default class="main">
        <default class="GEN3">
            <joint armature="0.01"/>
        </default>
        <default class="2F-85">
            <joint armature="0.08" damping="5"/>
        </default>
    </default>
    <asset>
        <texture type="2d" name="texplane" builtin="checker" mark="cross" rgb1="0.8 0.9 1" rgb2="0.6 0.8 0.8" markrgb="0.8 0.8 0.8" width="512" height="512"/>
        <material name="matplane" texture="texplane" texuniform="true" reflectance="0.3"/>
        <mesh name="base_link" file="base_link.STL"/>
        <mesh name="shoulder_link" file="shoulder_link.STL"/>
        <mesh name="half_arm_1_link" file="half_arm_1_link.STL"/>
        <mesh name="half_arm_2_link" file="half_arm_2_link.STL"/>
        <mesh name="forearm_link" file="forearm_link.STL"/>
        <mesh name="spherical_wrist_1_link" file="spherical_wrist_1_link.STL"/>
        <mesh name="spherical_wrist_2_link" file="spherical_wrist_2_link.STL"/>
        <mesh name="bracelet_link" file="bracelet_link.STL"/>
        <mesh name="robotiq_85_base_link" file="robotiq_85_base_link.stl"/>
        <mesh name="robotiq_85_knuckle_link" file="robotiq_85_knuckle_link.stl"/>
        <mesh name="robotiq_85_finger_link" file="robotiq_85_finger_link.stl"/>
        <mesh name="robotiq_85_inner_knuckle_link" file="robotiq_85_inner_knuckle_link.stl"/>
        <mesh name="robotiq_85_finger_tip_link" file="robotiq_85_finger_tip_link.stl"/>
    </asset>
    <worldbody>
        <geom size="0 0 0.1" type="plane" material="matplane"/>
        <light pos="0 0 100" dir="0 0 -1" castshadow="false" diffuse="0.5 0.5 0.5"/>
        <body name="top" pos="0 0 0">
            <camera name="realsense-top" pos="0.13 0 2.1" fovy="41"/>
        </body>
        <body name="front" pos="0 0 0">
            <camera name="realsense-front" pos="1.37 0 1.12" quat="0.500398 -0.5 0.5 -0.499602" fovy="41"/>
        </body>
        <body name="side-1" pos="0 0 0">
            <camera name="realsense-side-1" pos="0.13 1.5 1.12" quat="0.707388 -0.706825 0 0" fovy="41"/>
        </body>
        <body name="side-2" pos="0 0 0">
            <camera name="realsense-side-2" pos="0.13 -1.5 1.12" quat="0.000563312 0.000562864 -0.706825 0.707388" fovy="41"/>
        </body>
        <body name="Gen3_robot" pos="-0.07 0 0.82">
            <geom type="mesh" rgba="0.75294 0.75294 0.75294 1" mesh="base_link"/>
            <body name="shoulder_link" pos="0 0 0.15643" quat="-3.67321e-06 1 0 0">
                <joint name="robot0:joint_1" class="GEN3" pos="0 0 0" axis="0 0 1"/>
                <geom type="mesh" rgba="0.75294 0.75294 0.75294 1" mesh="shoulder_link"/>
                <body name="half_arm_1_link" pos="0 0.005375 -0.12838" quat="0.707105 0.707108 0 0">
                    <joint name="robot0:joint_2" class="GEN3" pos="0 0 0" axis="0 0 1" limited="true" range="-2.41 2.41"/>
                    <geom type="mesh" rgba="0.75294 0.75294 0.75294 1" mesh="half_arm_1_link"/>
                    <body name="half_arm_2_link" pos="0 -0.21038 -0.006375" quat="0.707105 -0.707108 0 0">
                        <joint name="robot0:joint_3" class="GEN3" pos="0 0 0" axis="0 0 1"/>
                        <geom type="mesh" rgba="0.75294 0.75294 0.75294 1" mesh="half_arm_2_link"/>
                        <body name="forearm_link" pos="0 0.006375 -0.21038" quat="0.707105 0.707108 0 0">
                            <joint name="robot0:joint_4" class="GEN3" pos="0 0 0" axis="0 0 1" limited="true" range="-2.66 2.66"/>
                            <geom type="mesh" rgba="0.75294 0.75294 0.75294 1" mesh="forearm_link"/>
                            <body name="spherical_wrist_1_link" pos="0 -0.20843 -0.006375" quat="0.707105 -0.707108 0 0">
                                <joint name="robot0:joint_5" class="GEN3" pos="0 0 0" axis="0 0 1"/>
                                <geom type="mesh" rgba="0.75294 0.75294 0.75294 1" mesh="spherical_wrist_1_link"/>
                                <body name="spherical_wrist_2_link" pos="0 0.00017505 -0.10593" quat="0.707105 0.707108 0 0">
                                    <joint name="robot0:joint_6" class="GEN3" pos="0 0 0" axis="0 0 1" limited="true" range="-2.23 2.23"/>
                                    <geom type="mesh" rgba="0.75294 0.75294 0.75294 1" mesh="spherical_wrist_2_link"/>
                                    <body name="bracelet_link" pos="0 -0.10593 -0.00017505" quat="0.707105 -0.707108 0 0">
                                        <joint name="robot0:joint_7" class="GEN3" pos="0 0 0" axis="0 0 1"/>
                                        <geom type="mesh" rgba="0.75294 0.75294 0.75294 1" mesh="bracelet_link"/>
                                        <geom pos="0 0 -0.061525" quat="-0.5 0.500398 -0.499602 -0.5" type="mesh" mesh="robotiq_85_base_link"/>
                                        <site name="robot0:0grip0" pos="0 0 -0.1" size="0.03" rgba="0 1 0 0"/>
                                        <site name="robot0:grip" pos="0 0 -0.21" size="0.01" rgba="0 1 0 0"/>
                                        <site name="gf1b_s" pos="-0.0126511 -1.01133e-05 -0.122955" size="0.002"/>
                                        <site name="gf2b_s" pos="0.0127489 1.01133e-05 -0.122935" size="0.002"/>
                                        <camera name="realsense" pos="0.0275 -0.066 -0.0585" fovy="41"/>
                                        <body name="gripper_finger1_knuckle_link" pos="-0.0305574 -2.43685e-05 -0.116454" quat="-0.500399 -0.499999 -0.500001 0.499601">
                                            <joint name="robot0:gripper_finger1_joint" class="2F-85" pos="0 0 0" axis="0 0 1" limited="true" range="0 0.804"/>
                                            <geom type="mesh" mesh="robotiq_85_knuckle_link"/>
                                            <body name="gripper_finger1_knuckle2_link" pos="0 0 0">
                                                <joint name="gripper_finger1_joint2" class="2F-85" pos="-0.00408552 -0.031486 0" axis="0 0 1" limited="true" range="0 0.804"/>
                                                <geom pos="-0.00408552 -0.031486 0" type="mesh" mesh="robotiq_85_finger_link"/>
                                                <body name="gripper_finger1_finger_tip_link" pos="0.05 -0.02 0">
                                                    <joint name="gripper_finger1_finger_tip_joint" class="2F-85" pos="-0.0066 -0.017245 0" axis="0 0 1" stiffness="50" range="0 0.804"/>
                                                    <geom type="mesh" condim="4" friction="0 0 0" solref="0.01 1" solimp="0.99 0.99 0.01 0.5 2" mesh="robotiq_85_finger_tip_link"/>
                                                    <geom name="tip_left_pivot" size="0.0018" pos="0.038 0.00925 0" condim="4" friction="1.2 0.005 0.0001" solref="0.01 1" solimp="0.99 0.99 0.01 0.5 2" rgba="0 0.7 0.1 1"/>
                                                    <geom name="tip_left_pivot_slip" size="0.0024" pos="0.038 0.00925 0" condim="4" friction="0.5 0.005 0.0001" solref="0.01 1" solimp="0.95 0.95 0.01 0.5 2" rgba="0 0.7 0.1 1"/>
                                                    <geom name="tip_left_rubber" size="0.019 0.001 0.011" pos="0.025 0.00925 0" type="box" condim="4" friction="1 0.08 0.0001" solref="0.01 1" solimp="0.98 0.98 0.01 0.5 6" rgba="1.5 0.7 0.1 1"/>
                                                    <body name="gripper_finger1_inner_knuckle_link" pos="-0.0430396 0.0375994 0">
                                                        <joint name="gripper_finger1_inner_knuckle_joint" class="2F-85" pos="0.0430396 -0.0375994 0" axis="0 0 1" limited="true" range="0 0.804"/>
                                                        <geom type="mesh" mesh="robotiq_85_inner_knuckle_link"/>
                                                        <site name="gf1a_s" pos="0 0 0" size="0.002" rgba="0.9 0.1 0.1 1"/>
                                                    </body>
                                                </body>
                                            </body>
                                        </body>
                                        <body name="gripper_finger2_knuckle_link" pos="0.0306448 2.43685e-05 -0.116405" quat="-0.5 0.500398 -0.499602 -0.5">
                                            <joint name="robot0:gripper_finger2_joint" class="2F-85" pos="0 0 0" axis="0 0 1" limited="true" range="0 0.804"/>
                                            <geom type="mesh" mesh="robotiq_85_knuckle_link"/>
                                            <body name="gripper_finger2_knuckle2_link" pos="0 0 0">
                                                <joint name="gripper_finger2_joint2" class="2F-85" pos="-0.00408552 -0.031486 0" axis="0 0 1" limited="true" range="0 0.804"/>
                                                <geom pos="-0.00408552 -0.031486 0" type="mesh" mesh="robotiq_85_finger_link"/>
                                                <body name="gripper_finger2_finger_tip_link" pos="0.05 -0.02 0">
                                                    <joint name="gripper_finger2_finger_tip_joint" class="2F-85" pos="-0.0066 -0.017245 0" axis="0 0 1" stiffness="50" range="0 0.804"/>
                                                    <geom type="mesh" condim="4" friction="0 0 0" solref="0.01 1" solimp="0.99 0.99 0.01 0.5 2" mesh="robotiq_85_finger_tip_link"/>
                                                    <geom name="tip_right_pivot" size="0.0018" pos="0.038 0.00925 0" condim="4" friction="1.2 0.01 0.0001" solref="0.01 1" solimp="0.99 0.99 0.01 0.5 2" rgba="0 0.7 0.1 1"/>
                                                    <geom name="tip_right_pivot_slip" size="0.0024" pos="0.038 0.00925 0" condim="4" friction="0.5 0.005 0.0001" solref="0.01 1" solimp="0.95 0.95 0.01 0.5 2" rgba="0 0.7 0.1 1"/>
                                                    <geom name="tip_right_rubber" size="0.019 0.001 0.011" pos="0.025 0.00925 0" type="box" condim="4" friction="1 0.08 0.0001" solref="0.01 1" solimp="0.98 0.98 0.01 0.5 6" rgba="1.5 0.7 0.1 1"/>
                                                    <body name="gripper_finger2_inner_knuckle_link" pos="-0.0430396 0.0375994 0">
                                                        <joint name="gripper_finger2_inner_knuckle_joint" class="2F-85" pos="0.0430396 -0.0375994 0" axis="0 0 1" limited="true" range="0 0.804"/>
                                                        <geom type="mesh" mesh="robotiq_85_inner_knuckle_link"/>
                                                        <site name="gf2a_s" pos="0 0 0" size="0.002" rgba="0.9 0.1 0.1 1"/>
                                                    </body>
                                                </body>
                                            </body>
                                        </body>
                                    </body>
                                </body>
                            </body>
                        </body>
                    </body>
                </body>
            </body>
        </body>
        <body name="Table" pos="0.475 0 0.8">
            <geom size="0.6 0.3 0.015" type="box" condim="4" friction="0.25 0.005 0.0001" solref="0.01 1" solimp="0.95 0.95 0.01 0.5 2" rgba="0.8 0.2 0.1 1"/>
            <geom size="0.0135 0.2" pos="-0.575 -0.275 -0.2" type="cylinder" rgba="0.8 0.2 0.1 1"/>
            <geom size="0.0135 0.2" pos="-0.575 0.275 -0.2" type="cylinder" rgba="0.8 0.2 0.1 1"/>
            <geom size="0.0135 0.2" pos="0.575 -0.275 -0.2" type="cylinder" rgba="0.8 0.2 0.1 1"/>
            <geom size="0.0135 0.2" pos="0.575 0.275 -0.2" type="cylinder" rgba="0.8 0.2 0.1 1"/>
            <geom name="spheret0" size="0.000152997" pos="-0.234925 0.0720718 0.015" condim="4" friction="0.25 0.005 0.0001" solref="0.01 1" solimp="0.95 0.95 0.01 0.5 2" rgba="1 1 1 1"/>
            <geom name="spheret1" size="0.00018159" pos="0.34931 -0.0817079 0.015" condim="4" friction="0.25 0.005 0.0001" solref="0.01 1" solimp="0.95 0.95 0.01 0.5 2" rgba="1 1 1 1"/>
            <geom name="spheret2" size="9.96946e-05" pos="0.20738 0.0361431 0.015" condim="4" friction="0.25 0.005 0.0001" solref="0.01 1" solimp="0.95 0.95 0.01 0.5 2" rgba="1 1 1 1"/>
            <geom name="spheret3" size="0.000197355" pos="0.337193 0.0100744 0.015" condim="4" friction="0.25 0.005 0.0001" solref="0.01 1" solimp="0.95 0.95 0.01 0.5 2" rgba="1 1 1 1"/>
            <geom name="spheret4" size="0.000118122" pos="-0.175655 0.238634 0.015" condim="4" friction="0.25 0.005 0.0001" solref="0.01 1" solimp="0.95 0.95 0.01 0.5 2" rgba="1 1 1 1"/>
            <geom name="spheret5" size="0.000175152" pos="-0.00465095 0.221934 0.015" condim="4" friction="0.25 0.005 0.0001" solref="0.01 1" solimp="0.95 0.95 0.01 0.5 2" rgba="1 1 1 1"/>
            <geom name="spheret6" size="0.000177813" pos="0.513012 0.0600854 0.015" condim="4" friction="0.25 0.005 0.0001" solref="0.01 1" solimp="0.95 0.95 0.01 0.5 2" rgba="1 1 1 1"/>
            <geom name="spheret7" size="0.000179779" pos="-0.0179859 -0.171913 0.015" condim="4" friction="0.25 0.005 0.0001" solref="0.01 1" solimp="0.95 0.95 0.01 0.5 2" rgba="1 1 1 1"/>
            <geom name="spheret8" size="7.42974e-05" pos="-0.138564 0.0256015 0.015" condim="4" friction="0.25 0.005 0.0001" solref="0.01 1" solimp="0.95 0.95 0.01 0.5 2" rgba="1 1 1 1"/>
            <geom name="spheret9" size="0.000146893" pos="-0.45887 -0.190882 0.015" condim="4" friction="0.25 0.005 0.0001" solref="0.01 1" solimp="0.95 0.95 0.01 0.5 2" rgba="1 1 1 1"/>
            <geom name="spheret10" size="0.000118304" pos="0.0220574 0.0730965 0.015" condim="4" friction="0.25 0.005 0.0001" solref="0.01 1" solimp="0.95 0.95 0.01 0.5 2" rgba="1 1 1 1"/>
            <geom name="spheret11" size="0.000103172" pos="-0.427869 0.0987149 0.015" condim="4" friction="0.25 0.005 0.0001" solref="0.01 1" solimp="0.95 0.95 0.01 0.5 2" rgba="1 1 1 1"/>
            <geom name="spheret12" size="0.000187187" pos="-0.0227312 0.184053 0.015" condim="4" friction="0.25 0.005 0.0001" solref="0.01 1" solimp="0.95 0.95 0.01 0.5 2" rgba="1 1 1 1"/>
            <geom name="spheret13" size="6.96012e-05" pos="-0.4702 0.204847 0.015" condim="4" friction="0.25 0.005 0.0001" solref="0.01 1" solimp="0.95 0.95 0.01 0.5 2" rgba="1 1 1 1"/>
            <geom name="spheret14" size="0.000135863" pos="-0.433343 0.106594 0.015" condim="4" friction="0.25 0.005 0.0001" solref="0.01 1" solimp="0.95 0.95 0.01 0.5 2" rgba="1 1 1 1"/>
            <geom name="spheret15" size="7.92684e-05" pos="-0.314197 -0.09661 0.015" condim="4" friction="0.25 0.005 0.0001" solref="0.01 1" solimp="0.95 0.95 0.01 0.5 2" rgba="1 1 1 1"/>
            <geom name="spheret16" size="0.000129729" pos="0.0810576 0.0644015 0.015" condim="4" friction="0.25 0.005 0.0001" solref="0.01 1" solimp="0.95 0.95 0.01 0.5 2" rgba="1 1 1 1"/>
            <geom name="spheret17" size="0.000131628" pos="-0.43433 -0.292455 0.015" condim="4" friction="0.25 0.005 0.0001" solref="0.01 1" solimp="0.95 0.95 0.01 0.5 2" rgba="1 1 1 1"/>
            <geom name="spheret18" size="0.000184246" pos="0.412358 -0.00633809 0.015" condim="4" friction="0.25 0.005 0.0001" solref="0.01 1" solimp="0.95 0.95 0.01 0.5 2" rgba="1 1 1 1"/>
            <geom name="spheret19" size="9.53249e-05" pos="-0.222734 0.182274 0.015" condim="4" friction="0.25 0.005 0.0001" solref="0.01 1" solimp="0.95 0.95 0.01 0.5 2" rgba="1 1 1 1"/>
            <geom name="spheret20" size="0.000177957" pos="0.261694 -0.180269 0.015" condim="4" friction="0.25 0.005 0.0001" solref="0.01 1" solimp="0.95 0.95 0.01 0.5 2" rgba="1 1 1 1"/>
            <geom name="spheret21" size="5.9722e-05" pos="0.0157028 -0.172719 0.015" condim="4" friction="0.25 0.005 0.0001" solref="0.01 1" solimp="0.95 0.95 0.01 0.5 2" rgba="1 1 1 1"/>
            <geom name="spheret22" size="8.15379e-05" pos="0.395483 -0.0957496 0.015" condim="4" friction="0.25 0.005 0.0001" solref="0.01 1" solimp="0.95 0.95 0.01 0.5 2" rgba="1 1 1 1"/>
            <geom name="spheret23" size="5.35478e-05" pos="-0.113539 -0.0526496 0.015" condim="4" friction="0.25 0.005 0.0001" solref="0.01 1" solimp="0.95 0.95 0.01 0.5 2" rgba="1 1 1 1"/>
            <geom name="spheret24" size="0.00013462" pos="-0.578179 -0.0464134 0.015" condim="4" friction="0.25 0.005 0.0001" solref="0.01 1" solimp="0.95 0.95 0.01 0.5 2" rgba="1 1 1 1"/>
            <geom name="spheret25" size="0.000175737" pos="0.128821 0.227914 0.015" condim="4" friction="0.25 0.005 0.0001" solref="0.01 1" solimp="0.95 0.95 0.01 0.5 2" rgba="1 1 1 1"/>
            <geom name="spheret26" size="9.89009e-05" pos="-0.123663 -0.277607 0.015" condim="4" friction="0.25 0.005 0.0001" solref="0.01 1" solimp="0.95 0.95 0.01 0.5 2" rgba="1 1 1 1"/>
            <geom name="spheret27" size="0.000100815" pos="-0.507723 -0.0481396 0.015" condim="4" friction="0.25 0.005 0.0001" solref="0.01 1" solimp="0.95 0.95 0.01 0.5 2" rgba="1 1 1 1"/>
            <geom name="spheret28" size="0.000110025" pos="-0.264865 0.195674 0.015" condim="4" friction="0.25 0.005 0.0001" solref="0.01 1" solimp="0.95 0.95 0.01 0.5 2" rgba="1 1 1 1"/>
            <geom name="spheret29" size="8.7163e-05" pos="-0.090761 0.00127781 0.015" condim="4" friction="0.25 0.005 0.0001" solref="0.01 1" solimp="0.95 0.95 0.01 0.5 2" rgba="1 1 1 1"/>
            <geom name="spheret30" size="6.73751e-05" pos="-0.400554 0.285564 0.015" condim="4" friction="0.25 0.005 0.0001" solref="0.01 1" solimp="0.95 0.95 0.01 0.5 2" rgba="1 1 1 1"/>
            <geom name="spheret31" size="0.000156941" pos="0.497473 -0.0734461 0.015" condim="4" friction="0.25 0.005 0.0001" solref="0.01 1" solimp="0.95 0.95 0.01 0.5 2" rgba="1 1 1 1"/>
            <geom name="spheret32" size="7.98487e-05" pos="-0.581455 0.033725 0.015" condim="4" friction="0.25 0.005 0.0001" solref="0.01 1" solimp="0.95 0.95 0.01 0.5 2" rgba="1 1 1 1"/>
            <geom name="spheret33" size="6.2461e-05" pos="-0.590752 0.16949 0.015" condim="4" friction="0.25 0.005 0.0001" solref="0.01 1" solimp="0.95 0.95 0.01 0.5 2" rgba="1 1 1 1"/>
            <geom name="spheret34" size="0.000133596" pos="-0.424666 0.186897 0.015" condim="4" friction="0.25 0.005 0.0001" solref="0.01 1" solimp="0.95 0.95 0.01 0.5 2" rgba="1 1 1 1"/>
            <geom name="spheret35" size="0.000165657" pos="-0.171658 0.000250154 0.015" condim="4" friction="0.25 0.005 0.0001" solref="0.01 1" solimp="0.95 0.95 0.01 0.5 2" rgba="1 1 1 1"/>
            <geom name="spheret36" size="0.00015107" pos="0.364161 -0.259618 0.015" condim="4" friction="0.25 0.005 0.0001" solref="0.01 1" solimp="0.95 0.95 0.01 0.5 2" rgba="1 1 1 1"/>
            <geom name="spheret37" size="6.99755e-05" pos="-0.197598 -0.0878939 0.015" condim="4" friction="0.25 0.005 0.0001" solref="0.01 1" solimp="0.95 0.95 0.01 0.5 2" rgba="1 1 1 1"/>
            <geom name="spheret38" size="5.44382e-05" pos="0.356509 0.0335314 0.015" condim="4" friction="0.25 0.005 0.0001" solref="0.01 1" solimp="0.95 0.95 0.01 0.5 2" rgba="1 1 1 1"/>
            <geom name="spheret39" size="0.000188105" pos="0.0968 0.207429 0.015" condim="4" friction="0.25 0.005 0.0001" solref="0.01 1" solimp="0.95 0.95 0.01 0.5 2" rgba="1 1 1 1"/>
            <geom name="spheret40" size="5.28895e-05" pos="0.556415 0.0837714 0.015" condim="4" friction="0.25 0.005 0.0001" solref="0.01 1" solimp="0.95 0.95 0.01 0.5 2" rgba="1 1 1 1"/>
            <geom name="spheret41" size="0.000107934" pos="0.017836 -0.115613 0.015" condim="4" friction="0.25 0.005 0.0001" solref="0.01 1" solimp="0.95 0.95 0.01 0.5 2" rgba="1 1 1 1"/>
            <geom name="spheret42" size="0.000164036" pos="-0.157657 0.169838 0.015" condim="4" friction="0.25 0.005 0.0001" solref="0.01 1" solimp="0.95 0.95 0.01 0.5 2" rgba="1 1 1 1"/>
            <geom name="spheret43" size="0.000158845" pos="0.275241 0.27963 0.015" condim="4" friction="0.25 0.005 0.0001" solref="0.01 1" solimp="0.95 0.95 0.01 0.5 2" rgba="1 1 1 1"/>
            <geom name="spheret44" size="8.4725e-05" pos="-0.118217 -0.152405 0.015" condim="4" friction="0.25 0.005 0.0001" solref="0.01 1" solimp="0.95 0.95 0.01 0.5 2" rgba="1 1 1 1"/>
            <geom name="spheret45" size="0.000180258" pos="0.302534 -0.268568 0.015" condim="4" friction="0.25 0.005 0.0001" solref="0.01 1" solimp="0.95 0.95 0.01 0.5 2" rgba="1 1 1 1"/>
            <geom name="spheret46" size="7.51046e-05" pos="-0.304204 0.191315 0.015" condim="4" friction="0.25 0.005 0.0001" solref="0.01 1" solimp="0.95 0.95 0.01 0.5 2" rgba="1 1 1 1"/>
            <geom name="spheret47" size="0.000194006" pos="0.137076 0.0297882 0.015" condim="4" friction="0.25 0.005 0.0001" solref="0.01 1" solimp="0.95 0.95 0.01 0.5 2" rgba="1 1 1 1"/>
            <geom name="spheret48" size="0.000160377" pos="-0.0312878 0.0934989 0.015" condim="4" friction="0.25 0.005 0.0001" solref="0.01 1" solimp="0.95 0.95 0.01 0.5 2" rgba="1 1 1 1"/>
            <geom name="spheret49" size="0.000112466" pos="0.230862 -0.106267 0.015" condim="4" friction="0.25 0.005 0.0001" solref="0.01 1" solimp="0.95 0.95 0.01 0.5 2" rgba="1 1 1 1"/>
            <geom name="spheret50" size="0.000153734" pos="0.470315 -0.275236 0.015" condim="4" friction="0.25 0.005 0.0001" solref="0.01 1" solimp="0.95 0.95 0.01 0.5 2" rgba="1 1 1 1"/>
            <geom name="spheret51" size="6.88216e-05" pos="-0.0261001 -0.146999 0.015" condim="4" friction="0.25 0.005 0.0001" solref="0.01 1" solimp="0.95 0.95 0.01 0.5 2" rgba="1 1 1 1"/>
            <geom name="spheret52" size="0.000160657" pos="-0.14309 0.0265302 0.015" condim="4" friction="0.25 0.005 0.0001" solref="0.01 1" solimp="0.95 0.95 0.01 0.5 2" rgba="1 1 1 1"/>
            <geom name="spheret53" size="0.000101716" pos="0.128711 -0.178114 0.015" condim="4" friction="0.25 0.005 0.0001" solref="0.01 1" solimp="0.95 0.95 0.01 0.5 2" rgba="1 1 1 1"/>
            <geom name="spheret54" size="0.000146175" pos="-0.0293345 0.255626 0.015" condim="4" friction="0.25 0.005 0.0001" solref="0.01 1" solimp="0.95 0.95 0.01 0.5 2" rgba="1 1 1 1"/>
            <geom name="spheret55" size="7.70182e-05" pos="-0.191945 0.178934 0.015" condim="4" friction="0.25 0.005 0.0001" solref="0.01 1" solimp="0.95 0.95 0.01 0.5 2" rgba="1 1 1 1"/>
            <geom name="spheret56" size="0.000157577" pos="0.363115 -0.157233 0.015" condim="4" friction="0.25 0.005 0.0001" solref="0.01 1" solimp="0.95 0.95 0.01 0.5 2" rgba="1 1 1 1"/>
            <geom name="spheret57" size="0.000180246" pos="0.337363 -0.0559293 0.015" condim="4" friction="0.25 0.005 0.0001" solref="0.01 1" solimp="0.95 0.95 0.01 0.5 2" rgba="1 1 1 1"/>
            <geom name="spheret58" size="0.000189916" pos="-0.312517 -0.275448 0.015" condim="4" friction="0.25 0.005 0.0001" solref="0.01 1" solimp="0.95 0.95 0.01 0.5 2" rgba="1 1 1 1"/>
            <geom name="spheret59" size="0.000191425" pos="0.291147 -0.0678861 0.015" condim="4" friction="0.25 0.005 0.0001" solref="0.01 1" solimp="0.95 0.95 0.01 0.5 2" rgba="1 1 1 1"/>
            <geom name="spheret60" size="0.00014745" pos="-0.576961 0.0412996 0.015" condim="4" friction="0.25 0.005 0.0001" solref="0.01 1" solimp="0.95 0.95 0.01 0.5 2" rgba="1 1 1 1"/>
            <geom name="spheret61" size="0.000164077" pos="0.417864 0.283161 0.015" condim="4" friction="0.25 0.005 0.0001" solref="0.01 1" solimp="0.95 0.95 0.01 0.5 2" rgba="1 1 1 1"/>
            <geom name="spheret62" size="5.44007e-05" pos="0.319488 -0.201366 0.015" condim="4" friction="0.25 0.005 0.0001" solref="0.01 1" solimp="0.95 0.95 0.01 0.5 2" rgba="1 1 1 1"/>
            <geom name="spheret63" size="0.000173069" pos="-0.480951 -0.299578 0.015" condim="4" friction="0.25 0.005 0.0001" solref="0.01 1" solimp="0.95 0.95 0.01 0.5 2" rgba="1 1 1 1"/>
            <geom name="spheret64" size="0.00014077" pos="0.54948 0.17829 0.015" condim="4" friction="0.25 0.005 0.0001" solref="0.01 1" solimp="0.95 0.95 0.01 0.5 2" rgba="1 1 1 1"/>
            <geom name="spheret65" size="0.000151555" pos="-0.0633744 0.109751 0.015" condim="4" friction="0.25 0.005 0.0001" solref="0.01 1" solimp="0.95 0.95 0.01 0.5 2" rgba="1 1 1 1"/>
            <geom name="spheret66" size="0.000138876" pos="0.0346404 0.0909153 0.015" condim="4" friction="0.25 0.005 0.0001" solref="0.01 1" solimp="0.95 0.95 0.01 0.5 2" rgba="1 1 1 1"/>
            <geom name="spheret67" size="0.000128698" pos="-0.479439 -0.273052 0.015" condim="4" friction="0.25 0.005 0.0001" solref="0.01 1" solimp="0.95 0.95 0.01 0.5 2" rgba="1 1 1 1"/>
            <geom name="spheret68" size="0.00014005" pos="0.183427 0.241457 0.015" condim="4" friction="0.25 0.005 0.0001" solref="0.01 1" solimp="0.95 0.95 0.01 0.5 2" rgba="1 1 1 1"/>
            <geom name="spheret69" size="0.000171456" pos="-0.315726 -0.120522 0.015" condim="4" friction="0.25 0.005 0.0001" solref="0.01 1" solimp="0.95 0.95 0.01 0.5 2" rgba="1 1 1 1"/>
            <geom name="spheret70" size="0.000143976" pos="0.227056 -0.0140463 0.015" condim="4" friction="0.25 0.005 0.0001" solref="0.01 1" solimp="0.95 0.95 0.01 0.5 2" rgba="1 1 1 1"/>
            <geom name="spheret71" size="0.000157863" pos="0.129271 0.201593 0.015" condim="4" friction="0.25 0.005 0.0001" solref="0.01 1" solimp="0.95 0.95 0.01 0.5 2" rgba="1 1 1 1"/>
            <geom name="spheret72" size="0.00019755" pos="0.0632279 -0.106576 0.015" condim="4" friction="0.25 0.005 0.0001" solref="0.01 1" solimp="0.95 0.95 0.01 0.5 2" rgba="1 1 1 1"/>
            <geom name="spheret73" size="5.93559e-05" pos="0.0711782 0.274219 0.015" condim="4" friction="0.25 0.005 0.0001" solref="0.01 1" solimp="0.95 0.95 0.01 0.5 2" rgba="1 1 1 1"/>
            <geom name="spheret74" size="0.000100081" pos="-0.353306 0.174151 0.015" condim="4" friction="0.25 0.005 0.0001" solref="0.01 1" solimp="0.95 0.95 0.01 0.5 2" rgba="1 1 1 1"/>
            <geom name="spheret75" size="0.000137103" pos="-0.119268 -0.253568 0.015" condim="4" friction="0.25 0.005 0.0001" solref="0.01 1" solimp="0.95 0.95 0.01 0.5 2" rgba="1 1 1 1"/>
            <geom name="spheret76" size="0.000199474" pos="-0.0511975 -0.298123 0.015" condim="4" friction="0.25 0.005 0.0001" solref="0.01 1" solimp="0.95 0.95 0.01 0.5 2" rgba="1 1 1 1"/>
            <geom name="spheret77" size="0.000104001" pos="-0.118646 0.129493 0.015" condim="4" friction="0.25 0.005 0.0001" solref="0.01 1" solimp="0.95 0.95 0.01 0.5 2" rgba="1 1 1 1"/>
            <geom name="spheret78" size="7.77378e-05" pos="-0.471947 0.297107 0.015" condim="4" friction="0.25 0.005 0.0001" solref="0.01 1" solimp="0.95 0.95 0.01 0.5 2" rgba="1 1 1 1"/>
            <geom name="spheret79" size="8.78488e-05" pos="-0.335798 0.277068 0.015" condim="4" friction="0.25 0.005 0.0001" solref="0.01 1" solimp="0.95 0.95 0.01 0.5 2" rgba="1 1 1 1"/>
            <geom name="spheret80" size="0.000145808" pos="-0.0459073 0.212927 0.015" condim="4" friction="0.25 0.005 0.0001" solref="0.01 1" solimp="0.95 0.95 0.01 0.5 2" rgba="1 1 1 1"/>
            <geom name="spheret81" size="0.000107699" pos="-0.200778 0.0306709 0.015" condim="4" friction="0.25 0.005 0.0001" solref="0.01 1" solimp="0.95 0.95 0.01 0.5 2" rgba="1 1 1 1"/>
            <geom name="spheret82" size="5.03237e-05" pos="-0.423904 -0.00390377 0.015" condim="4" friction="0.25 0.005 0.0001" solref="0.01 1" solimp="0.95 0.95 0.01 0.5 2" rgba="1 1 1 1"/>
            <geom name="spheret83" size="0.000106465" pos="-0.366491 0.259493 0.015" condim="4" friction="0.25 0.005 0.0001" solref="0.01 1" solimp="0.95 0.95 0.01 0.5 2" rgba="1 1 1 1"/>
            <geom name="spheret84" size="6.6336e-05" pos="-0.331184 0.0768139 0.015" condim="4" friction="0.25 0.005 0.0001" solref="0.01 1" solimp="0.95 0.95 0.01 0.5 2" rgba="1 1 1 1"/>
            <geom name="spheret85" size="8.24376e-05" pos="-0.564329 -0.174866 0.015" condim="4" friction="0.25 0.005 0.0001" solref="0.01 1" solimp="0.95 0.95 0.01 0.5 2" rgba="1 1 1 1"/>
            <geom name="spheret86" size="0.00012863" pos="-0.163728 0.294752 0.015" condim="4" friction="0.25 0.005 0.0001" solref="0.01 1" solimp="0.95 0.95 0.01 0.5 2" rgba="1 1 1 1"/>
            <geom name="spheret87" size="0.000151783" pos="0.447762 -0.299004 0.015" condim="4" friction="0.25 0.005 0.0001" solref="0.01 1" solimp="0.95 0.95 0.01 0.5 2" rgba="1 1 1 1"/>
            <geom name="spheret88" size="9.7672e-05" pos="-0.523235 0.0363655 0.015" condim="4" friction="0.25 0.005 0.0001" solref="0.01 1" solimp="0.95 0.95 0.01 0.5 2" rgba="1 1 1 1"/>
            <geom name="spheret89" size="0.000195297" pos="-0.0901441 0.286546 0.015" condim="4" friction="0.25 0.005 0.0001" solref="0.01 1" solimp="0.95 0.95 0.01 0.5 2" rgba="1 1 1 1"/>
            <geom name="spheret90" size="0.000163126" pos="0.0531822 0.277352 0.015" condim="4" friction="0.25 0.005 0.0001" solref="0.01 1" solimp="0.95 0.95 0.01 0.5 2" rgba="1 1 1 1"/>
            <geom name="spheret91" size="8.61058e-05" pos="-0.277392 0.119603 0.015" condim="4" friction="0.25 0.005 0.0001" solref="0.01 1" solimp="0.95 0.95 0.01 0.5 2" rgba="1 1 1 1"/>
            <geom name="spheret92" size="5.88301e-05" pos="0.454702 -0.230447 0.015" condim="4" friction="0.25 0.005 0.0001" solref="0.01 1" solimp="0.95 0.95 0.01 0.5 2" rgba="1 1 1 1"/>
            <geom name="spheret93" size="6.43926e-05" pos="0.563296 0.216143 0.015" condim="4" friction="0.25 0.005 0.0001" solref="0.01 1" solimp="0.95 0.95 0.01 0.5 2" rgba="1 1 1 1"/>
            <geom name="spheret94" size="0.000137224" pos="-0.424275 -0.159766 0.015" condim="4" friction="0.25 0.005 0.0001" solref="0.01 1" solimp="0.95 0.95 0.01 0.5 2" rgba="1 1 1 1"/>
            <geom name="spheret95" size="0.000177025" pos="-0.434083 -0.132156 0.015" condim="4" friction="0.25 0.005 0.0001" solref="0.01 1" solimp="0.95 0.95 0.01 0.5 2" rgba="1 1 1 1"/>
            <geom name="spheret96" size="0.000191186" pos="0.329997 0.0593131 0.015" condim="4" friction="0.25 0.005 0.0001" solref="0.01 1" solimp="0.95 0.95 0.01 0.5 2" rgba="1 1 1 1"/>
            <geom name="spheret97" size="0.000163873" pos="0.403579 0.23882 0.015" condim="4" friction="0.25 0.005 0.0001" solref="0.01 1" solimp="0.95 0.95 0.01 0.5 2" rgba="1 1 1 1"/>
            <geom name="spheret98" size="0.00017221" pos="0.169174 0.187039 0.015" condim="4" friction="0.25 0.005 0.0001" solref="0.01 1" solimp="0.95 0.95 0.01 0.5 2" rgba="1 1 1 1"/>
            <geom name="spheret99" size="5.21414e-05" pos="0.240295 -0.132401 0.015" condim="4" friction="0.25 0.005 0.0001" solref="0.01 1" solimp="0.95 0.95 0.01 0.5 2" rgba="1 1 1 1"/>
            <site name="target0" pos="-0.1 -0.25 0.015" size="0.02 0.0001" type="cylinder" rgba="0 1 0 1"/>
        </body>
        <body name="ConSurf" pos="0.45 0 0.84">
            <joint name="object0:joint_x" pos="0 0 0" axis="1 0 0" type="slide" damping="0.01"/>
            <joint name="object0:joint_y" pos="0 0 0" axis="0 1 0" type="slide" damping="0.01"/>
            <joint name="object0:joint_z" pos="0 0 0" axis="0 0 1" type="slide" damping="0.01"/>
            <joint name="object0:joint_r" pos="0 0 0" axis="1 0 0" damping="0.01"/>
            <joint name="object0:joint_p" pos="0 0 0" axis="0 1 0" damping="0.01"/>
            <joint name="object0:joint_yw" pos="0 0 0" axis="0 0 1" damping="0.01"/>
            <geom name="ConSurf" size="0.035 0.015 0.025" type="box" priority="2" friction="0.45 0.005 0.0001" solref="0.01 1" solimp="0.95 0.95 0.01 0.5 2" rgba="0.999 0.999 0.999 1"/>
            <site name="object0" pos="0 0 -0.025" size="0.0001 0.0001" type="cylinder" rgba="0 1 0 1"/>
        </body>
    </worldbody>
    <equality>
        <tendon tendon1="gf1_t" polycoef="0 1 0 0 0" solref="0.01 1" solimp="0.99 0.99 0.001 0.5 2"/>
        <tendon tendon1="gf2_t" polycoef="0 1 0 0 0" solref="0.01 1" solimp="0.99 0.99 0.001 0.5 2"/>
    </equality>
    <tendon>
        <spatial name="gf1_t" stiffness="10" damping="0.2" width="2e-05" rgba="0.9 0.9 0.9 1">
            <site site="gf1a_s"/>
            <site site="gf1b_s"/>
        </spatial>
        <spatial name="gf2_t" stiffness="10" damping="0.2" width="2e-05" rgba="0.9 0.9 0.9 1">
            <site site="gf2a_s"/>
            <site site="gf2b_s"/>
        </spatial>
    </tendon>
    <actuator>
        <general name="Joint1" joint="robot0:joint_1" ctrllimited="true" ctrlrange="-39 39" gear="3 0 0 0 0 0"/>
        <general name="Joint2" joint="robot0:joint_2" ctrllimited="true" ctrlrange="-39 39" gear="3 0 0 0 0 0"/>
        <general name="Joint3" joint="robot0:joint_3" ctrllimited="true" ctrlrange="-39 39" gear="3 0 0 0 0 0"/>
        <general name="Joint4" joint="robot0:joint_4" ctrllimited="true" ctrlrange="-39 39" gear="3 0 0 0 0 0"/>
        <general name="Joint5" joint="robot0:joint_5" ctrllimited="true" ctrlrange="-19 19" gear="3 0 0 0 0 0"/>
        <general name="Joint6" joint="robot0:joint_6" ctrllimited="true" ctrlrange="-19 19" gear="3 0 0 0 0 0"/>
        <general name="Joint7" joint="robot0:joint_7" ctrllimited="true" ctrlrange="-19 19" gear="3 0 0 0 0 0"/>
        <general name="JointGL" joint="robot0:gripper_finger1_joint" ctrllimited="true" ctrlrange="0 1.5" forcerange="0 5" biastype="affine" gainprm="80 0 0 0 0 0 0 0 0 0" biasprm="0 -80 0 0 0 0 0 0 0 0"/>
        <general name="JointGR" joint="robot0:gripper_finger2_joint" ctrllimited="true" ctrlrange="0 1.5" forcerange="0 5" biastype="affine" gainprm="80 0 0 0 0 0 0 0 0 0" biasprm="0 -80 0 0 0 0 0 0 0 0"/>
    </actuator>
    <keyframe>
        <key time="1.7020000000000013" qpos="-0.0736817441790562 0.18530116489956297 -3.053494753419455 -1.9301109722568262 -0.01739705316940886 -1.0446872225509216 1.5903240864966037 -0.001238439590422543 -0.0011142028601810255 -0.0011682347462901078 0.005208318100973973 -0.0012387770156093618 -0.0011143350323186928 -0.001160060054679359 0.005191866920875197 0.0 0.0 -2.452499999999845e-05 0.0 0.0 0.0" qvel="1.1717857687565313e-05 3.2767411532145596e-07 -1.2810722577022106e-05 4.339936858095565e-07 5.644117996268204e-07 -1.4778450733393163e-07 -1.3034501622288547e-07 -4.249493389583326e-12 -4.305071486615646e-12 1.4480567216407946e-11 -1.2729367227230564e-11 4.190442523875497e-12 4.247400762836397e-12 -1.5227310459887327e-11 1.2015120964839293e-11 0.0 0.0 2.1649507620858009e-16 0.0 0.0 0.0"/>
    </keyframe>
</mujoco>