<?xml version="1.0" ?>
<mujoco model="gen3_robotiq_2f_85">
    <compiler angle="radian" meshdir="gen3/"/>
    <option cone="elliptic"/>
    <size njmax="500" nconmax="500"/>
    <visual>
        <global offwidth="1920" offheight="1043"/>
    </visual>
    <default class="main">
        <default class="GEN3">
            <joint armature="0.01"/>
        </default>
        <default class="2F-85">
            <joint armature="0.08" damping="5"/>
        </default>
    </default>
    <asset>
        <texture type="2d" name="texplane" builtin="checker" mark="cross" rgb1="0.8 0.9 1" rgb2="0.6 0.8 0.8" markrgb="0.8 0.8 0.8" width="512" height="512"/>
        <material name="matplane" texture="texplane" texuniform="true" reflectance="0.3"/>
        <mesh name="base_link" file="base_link.STL"/>
        <mesh name="shoulder_link" file="shoulder_link.STL"/>
        <mesh name="half_arm_1_link" file="half_arm_1_link.STL"/>
        <mesh name="half_arm_2_link" file="half_arm_2_link.STL"/>
        <mesh name="forearm_link" file="forearm_link.STL"/>
        <mesh name="spherical_wrist_1_link" file="spherical_wrist_1_link.STL"/>
        <mesh name="spherical_wrist_2_link" file="spherical_wrist_2_link.STL"/>
        <mesh name="bracelet_link" file="bracelet_link.STL"/>
        <mesh name="robotiq_85_base_link" file="robotiq_85_base_link.stl"/>
        <mesh name="robotiq_85_knuckle_link" file="robotiq_85_knuckle_link.stl"/>
        <mesh name="robotiq_85_finger_link" file="robotiq_85_finger_link.stl"/>
        <mesh name="robotiq_85_inner_knuckle_link" file="robotiq_85_inner_knuckle_link.stl"/>
        <mesh name="robotiq_85_finger_tip_link" file="robotiq_85_finger_tip_link.stl"/>
    </asset>
    <worldbody>
        <geom size="0 0 0.1" type="plane" material="matplane"/>
        <light pos="0 0 100" dir="0 0 -1" castshadow="false" diffuse="0.5 0.5 0.5"/>
        <body name="top" pos="0 0 0">
            <camera name="realsense-top" pos="0.53 0 2.52" fovy="41"/>
        </body>
        <body name="front" pos="0 0 0">
            <camera name="realsense-front" pos="1.37 0 1.12" quat="0.500398 -0.5 0.5 -0.499602" fovy="41"/>
        </body>
        <body name="side-1" pos="0 0 0">
            <camera name="realsense-side-1" pos="0.53 1.5 1.12" quat="0.707388 -0.706825 0 0" fovy="41"/>
        </body>
        <body name="side-2" pos="0 0 0">
            <camera name="realsense-side-2" pos="0.53 -1.5 1.12" quat="0.000563312 0.000562864 -0.706825 0.707388" fovy="41"/>
        </body>
        <body name="Gen3_robot" pos="-0.07 0 0.82">
            <geom type="mesh" rgba="0.75294 0.75294 0.75294 1" mesh="base_link"/>
            <body name="shoulder_link" pos="0 0 0.15643" quat="-3.67321e-06 1 0 0">
                <joint name="robot0:joint_1" class="GEN3" pos="0 0 0" axis="0 0 1"/>
                <geom type="mesh" rgba="0.75294 0.75294 0.75294 1" mesh="shoulder_link"/>
                <body name="half_arm_1_link" pos="0 0.005375 -0.12838" quat="0.707105 0.707108 0 0">
                    <joint name="robot0:joint_2" class="GEN3" pos="0 0 0" axis="0 0 1" limited="true" range="-2.41 2.41"/>
                    <geom type="mesh" rgba="0.75294 0.75294 0.75294 1" mesh="half_arm_1_link"/>
                    <body name="half_arm_2_link" pos="0 -0.21038 -0.006375" quat="0.707105 -0.707108 0 0">
                        <joint name="robot0:joint_3" class="GEN3" pos="0 0 0" axis="0 0 1"/>
                        <geom type="mesh" rgba="0.75294 0.75294 0.75294 1" mesh="half_arm_2_link"/>
                        <body name="forearm_link" pos="0 0.006375 -0.21038" quat="0.707105 0.707108 0 0">
                            <joint name="robot0:joint_4" class="GEN3" pos="0 0 0" axis="0 0 1" limited="true" range="-2.66 2.66"/>
                            <geom type="mesh" rgba="0.75294 0.75294 0.75294 1" mesh="forearm_link"/>
                            <body name="spherical_wrist_1_link" pos="0 -0.20843 -0.006375" quat="0.707105 -0.707108 0 0">
                                <joint name="robot0:joint_5" class="GEN3" pos="0 0 0" axis="0 0 1"/>
                                <geom type="mesh" rgba="0.75294 0.75294 0.75294 1" mesh="spherical_wrist_1_link"/>
                                <body name="spherical_wrist_2_link" pos="0 0.00017505 -0.10593" quat="0.707105 0.707108 0 0">
                                    <joint name="robot0:joint_6" class="GEN3" pos="0 0 0" axis="0 0 1" limited="true" range="-2.23 2.23"/>
                                    <geom type="mesh" rgba="0.75294 0.75294 0.75294 1" mesh="spherical_wrist_2_link"/>
                                    <body name="bracelet_link" pos="0 -0.10593 -0.00017505" quat="0.707105 -0.707108 0 0">
                                        <joint name="robot0:joint_7" class="GEN3" pos="0 0 0" axis="0 0 1"/>
                                        <geom type="mesh" rgba="0.75294 0.75294 0.75294 1" mesh="bracelet_link"/>
                                        <geom pos="0 0 -0.061525" quat="-0.5 0.500398 -0.499602 -0.5" type="mesh" mesh="robotiq_85_base_link"/>
                                        <site name="robot0:0grip0" pos="0 0 -0.1" size="0.03" rgba="0 1 0 0"/>
                                        <site name="robot0:grip" pos="0 0 -0.21" size="0.01" rgba="0 1 0 0"/>
                                        <site name="gf1b_s" pos="-0.0126511 -1.01133e-05 -0.122955" size="0.002"/>
                                        <site name="gf2b_s" pos="0.0127489 1.01133e-05 -0.122935" size="0.002"/>
                                        <camera name="realsense" pos="0.0275 -0.066 -0.0585" fovy="41"/>
                                        <body name="gripper_finger1_knuckle_link" pos="-0.0305574 -2.43685e-05 -0.116454" quat="-0.500399 -0.499999 -0.500001 0.499601">
                                            <joint name="robot0:gripper_finger1_joint" class="2F-85" pos="0 0 0" axis="0 0 1" limited="true" range="0 0.804"/>
                                            <geom type="mesh" mesh="robotiq_85_knuckle_link"/>
                                            <body name="gripper_finger1_knuckle2_link" pos="0 0 0">
                                                <joint name="gripper_finger1_joint2" class="2F-85" pos="-0.00408552 -0.031486 0" axis="0 0 1" limited="true" range="0 0.804"/>
                                                <geom pos="-0.00408552 -0.031486 0" type="mesh" mesh="robotiq_85_finger_link"/>
                                                <body name="gripper_finger1_finger_tip_link" pos="0.05 -0.02 0">
                                                    <joint name="gripper_finger1_finger_tip_joint" class="2F-85" pos="-0.0066 -0.017245 0" axis="0 0 1" stiffness="50" range="0 0.804"/>
                                                    <geom type="mesh" condim="4" friction="0 0 0" solref="0.01 1" solimp="0.99 0.99 0.01 0.5 2" mesh="robotiq_85_finger_tip_link"/>
                                                    <geom name="tip_left_pivot" size="0.0018" pos="0.038 0.00925 0" condim="4" friction="1.2 0.005 0.0001" solref="0.01 1" solimp="0.99 0.99 0.01 0.5 2" rgba="0 0.7 0.1 1"/>
                                                    <geom name="tip_left_pivot_slip" size="0.0024" pos="0.038 0.00925 0" condim="4" friction="0.5 0.005 0.0001" solref="0.01 1" solimp="0.95 0.95 0.01 0.5 2" rgba="0 0.7 0.1 1"/>
                                                    <geom name="tip_left_rubber" size="0.019 0.001 0.011" pos="0.025 0.00925 0" type="box" condim="4" friction="1 0.08 0.0001" solref="0.01 1" solimp="0.98 0.98 0.01 0.5 6" rgba="1.5 0.7 0.1 1"/>
                                                    <body name="gripper_finger1_inner_knuckle_link" pos="-0.0430396 0.0375994 0">
                                                        <joint name="gripper_finger1_inner_knuckle_joint" class="2F-85" pos="0.0430396 -0.0375994 0" axis="0 0 1" limited="true" range="0 0.804"/>
                                                        <geom type="mesh" mesh="robotiq_85_inner_knuckle_link"/>
                                                        <site name="gf1a_s" pos="0 0 0" size="0.002" rgba="0.9 0.1 0.1 1"/>
                                                    </body>
                                                </body>
                                            </body>
                                        </body>
                                        <body name="gripper_finger2_knuckle_link" pos="0.0306448 2.43685e-05 -0.116405" quat="-0.5 0.500398 -0.499602 -0.5">
                                            <joint name="robot0:gripper_finger2_joint" class="2F-85" pos="0 0 0" axis="0 0 1" limited="true" range="0 0.804"/>
                                            <geom type="mesh" mesh="robotiq_85_knuckle_link"/>
                                            <body name="gripper_finger2_knuckle2_link" pos="0 0 0">
                                                <joint name="gripper_finger2_joint2" class="2F-85" pos="-0.00408552 -0.031486 0" axis="0 0 1" limited="true" range="0 0.804"/>
                                                <geom pos="-0.00408552 -0.031486 0" type="mesh" mesh="robotiq_85_finger_link"/>
                                                <body name="gripper_finger2_finger_tip_link" pos="0.05 -0.02 0">
                                                    <joint name="gripper_finger2_finger_tip_joint" class="2F-85" pos="-0.0066 -0.017245 0" axis="0 0 1" stiffness="50" range="0 0.804"/>
                                                    <geom type="mesh" condim="4" friction="0 0 0" solref="0.01 1" solimp="0.99 0.99 0.01 0.5 2" mesh="robotiq_85_finger_tip_link"/>
                                                    <geom name="tip_right_pivot" size="0.0018" pos="0.038 0.00925 0" condim="4" friction="1.2 0.01 0.0001" solref="0.01 1" solimp="0.99 0.99 0.01 0.5 2" rgba="0 0.7 0.1 1"/>
                                                    <geom name="tip_right_pivot_slip" size="0.0024" pos="0.038 0.00925 0" condim="4" friction="0.5 0.005 0.0001" solref="0.01 1" solimp="0.95 0.95 0.01 0.5 2" rgba="0 0.7 0.1 1"/>
                                                    <geom name="tip_right_rubber" size="0.019 0.001 0.011" pos="0.025 0.00925 0" type="box" condim="4" friction="1 0.08 0.0001" solref="0.01 1" solimp="0.98 0.98 0.01 0.5 6" rgba="1.5 0.7 0.1 1"/>
                                                    <body name="gripper_finger2_inner_knuckle_link" pos="-0.0430396 0.0375994 0">
                                                        <joint name="gripper_finger2_inner_knuckle_joint" class="2F-85" pos="0.0430396 -0.0375994 0" axis="0 0 1" limited="true" range="0 0.804"/>
                                                        <geom type="mesh" mesh="robotiq_85_inner_knuckle_link"/>
                                                        <site name="gf2a_s" pos="0 0 0" size="0.002" rgba="0.9 0.1 0.1 1"/>
                                                    </body>
                                                </body>
                                            </body>
                                        </body>
                                    </body>
                                </body>
                            </body>
                        </body>
                    </body>
                </body>
            </body>
        </body>
        <body name="Table" pos="0.475 0 0.8">
            <geom size="0.6 0.3 0.015" type="box" condim="4" friction="0.25 0.005 0.0001" solref="0.01 1" solimp="0.95 0.95 0.01 0.5 2" rgba="0.8 0.2 0.1 1"/>
            <geom size="0.0135 0.2" pos="-0.575 -0.275 -0.2" type="cylinder" rgba="0.8 0.2 0.1 1"/>
            <geom size="0.0135 0.2" pos="-0.575 0.275 -0.2" type="cylinder" rgba="0.8 0.2 0.1 1"/>
            <geom size="0.0135 0.2" pos="0.575 -0.275 -0.2" type="cylinder" rgba="0.8 0.2 0.1 1"/>
            <geom size="0.0135 0.2" pos="0.575 0.275 -0.2" type="cylinder" rgba="0.8 0.2 0.1 1"/>
            <geom name="spheret0" size="0.000164053" pos="-0.512958 -0.0697431 0.015" condim="4" friction="0.25 0.005 0.0001" solref="0.01 1" solimp="0.95 0.95 0.01 0.5 2" rgba="1 1 1 1"/>
            <geom name="spheret1" size="7.00609e-05" pos="0.101103 0.0078632 0.015" condim="4" friction="0.25 0.005 0.0001" solref="0.01 1" solimp="0.95 0.95 0.01 0.5 2" rgba="1 1 1 1"/>
            <geom name="spheret2" size="8.95138e-05" pos="0.00267178 -0.0575134 0.015" condim="4" friction="0.25 0.005 0.0001" solref="0.01 1" solimp="0.95 0.95 0.01 0.5 2" rgba="1 1 1 1"/>
            <geom name="spheret3" size="7.97897e-05" pos="-0.528714 -0.280851 0.015" condim="4" friction="0.25 0.005 0.0001" solref="0.01 1" solimp="0.95 0.95 0.01 0.5 2" rgba="1 1 1 1"/>
            <geom name="spheret4" size="5.79668e-05" pos="0.211856 0.0353367 0.015" condim="4" friction="0.25 0.005 0.0001" solref="0.01 1" solimp="0.95 0.95 0.01 0.5 2" rgba="1 1 1 1"/>
            <geom name="spheret5" size="0.000148629" pos="-0.474946 0.16505 0.015" condim="4" friction="0.25 0.005 0.0001" solref="0.01 1" solimp="0.95 0.95 0.01 0.5 2" rgba="1 1 1 1"/>
            <geom name="spheret6" size="0.000104448" pos="-0.155261 -0.114072 0.015" condim="4" friction="0.25 0.005 0.0001" solref="0.01 1" solimp="0.95 0.95 0.01 0.5 2" rgba="1 1 1 1"/>
            <geom name="spheret7" size="0.00010627" pos="-0.238902 -0.133201 0.015" condim="4" friction="0.25 0.005 0.0001" solref="0.01 1" solimp="0.95 0.95 0.01 0.5 2" rgba="1 1 1 1"/>
            <geom name="spheret8" size="8.1472e-05" pos="0.417966 -0.164843 0.015" condim="4" friction="0.25 0.005 0.0001" solref="0.01 1" solimp="0.95 0.95 0.01 0.5 2" rgba="1 1 1 1"/>
            <geom name="spheret9" size="8.67675e-05" pos="0.312725 0.0872443 0.015" condim="4" friction="0.25 0.005 0.0001" solref="0.01 1" solimp="0.95 0.95 0.01 0.5 2" rgba="1 1 1 1"/>
            <geom name="spheret10" size="0.000159043" pos="0.293797 0.187063 0.015" condim="4" friction="0.25 0.005 0.0001" solref="0.01 1" solimp="0.95 0.95 0.01 0.5 2" rgba="1 1 1 1"/>
            <geom name="spheret11" size="9.98514e-05" pos="0.0412768 -0.198543 0.015" condim="4" friction="0.25 0.005 0.0001" solref="0.01 1" solimp="0.95 0.95 0.01 0.5 2" rgba="1 1 1 1"/>
            <geom name="spheret12" size="0.000116301" pos="-0.109137 -0.222359 0.015" condim="4" friction="0.25 0.005 0.0001" solref="0.01 1" solimp="0.95 0.95 0.01 0.5 2" rgba="1 1 1 1"/>
            <geom name="spheret13" size="0.000183895" pos="-0.207974 0.139203 0.015" condim="4" friction="0.25 0.005 0.0001" solref="0.01 1" solimp="0.95 0.95 0.01 0.5 2" rgba="1 1 1 1"/>
            <geom name="spheret14" size="0.000145885" pos="-0.230092 0.0464253 0.015" condim="4" friction="0.25 0.005 0.0001" solref="0.01 1" solimp="0.95 0.95 0.01 0.5 2" rgba="1 1 1 1"/>
            <geom name="spheret15" size="0.000130851" pos="-0.153424 0.0193225 0.015" condim="4" friction="0.25 0.005 0.0001" solref="0.01 1" solimp="0.95 0.95 0.01 0.5 2" rgba="1 1 1 1"/>
            <geom name="spheret16" size="8.62024e-05" pos="-0.206462 -0.2587 0.015" condim="4" friction="0.25 0.005 0.0001" solref="0.01 1" solimp="0.95 0.95 0.01 0.5 2" rgba="1 1 1 1"/>
            <geom name="spheret17" size="0.000195984" pos="-0.347219 -0.0447336 0.015" condim="4" friction="0.25 0.005 0.0001" solref="0.01 1" solimp="0.95 0.95 0.01 0.5 2" rgba="1 1 1 1"/>
            <geom name="spheret18" size="6.30607e-05" pos="-0.583946 0.0529593 0.015" condim="4" friction="0.25 0.005 0.0001" solref="0.01 1" solimp="0.95 0.95 0.01 0.5 2" rgba="1 1 1 1"/>
            <geom name="spheret19" size="0.000111839" pos="0.564356 0.210507 0.015" condim="4" friction="0.25 0.005 0.0001" solref="0.01 1" solimp="0.95 0.95 0.01 0.5 2" rgba="1 1 1 1"/>
            <geom name="spheret20" size="0.00011406" pos="-0.233665 0.264746 0.015" condim="4" friction="0.25 0.005 0.0001" solref="0.01 1" solimp="0.95 0.95 0.01 0.5 2" rgba="1 1 1 1"/>
            <geom name="spheret21" size="0.000128572" pos="-0.521951 -0.0310563 0.015" condim="4" friction="0.25 0.005 0.0001" solref="0.01 1" solimp="0.95 0.95 0.01 0.5 2" rgba="1 1 1 1"/>
            <geom name="spheret22" size="0.000113081" pos="-0.390025 0.0334053 0.015" condim="4" friction="0.25 0.005 0.0001" solref="0.01 1" solimp="0.95 0.95 0.01 0.5 2" rgba="1 1 1 1"/>
            <geom name="spheret23" size="0.000120003" pos="0.415886 0.186511 0.015" condim="4" friction="0.25 0.005 0.0001" solref="0.01 1" solimp="0.95 0.95 0.01 0.5 2" rgba="1 1 1 1"/>
            <geom name="spheret24" size="8.15233e-05" pos="0.296946 0.243638 0.015" condim="4" friction="0.25 0.005 0.0001" solref="0.01 1" solimp="0.95 0.95 0.01 0.5 2" rgba="1 1 1 1"/>
            <geom name="spheret25" size="7.94177e-05" pos="-0.1389 0.092022 0.015" condim="4" friction="0.25 0.005 0.0001" solref="0.01 1" solimp="0.95 0.95 0.01 0.5 2" rgba="1 1 1 1"/>
            <geom name="spheret26" size="5.93723e-05" pos="-0.260293 0.113829 0.015" condim="4" friction="0.25 0.005 0.0001" solref="0.01 1" solimp="0.95 0.95 0.01 0.5 2" rgba="1 1 1 1"/>
            <geom name="spheret27" size="8.18418e-05" pos="-0.284693 -0.205856 0.015" condim="4" friction="0.25 0.005 0.0001" solref="0.01 1" solimp="0.95 0.95 0.01 0.5 2" rgba="1 1 1 1"/>
            <geom name="spheret28" size="6.6151e-05" pos="-0.079602 0.126948 0.015" condim="4" friction="0.25 0.005 0.0001" solref="0.01 1" solimp="0.95 0.95 0.01 0.5 2" rgba="1 1 1 1"/>
            <geom name="spheret29" size="0.000172938" pos="0.279618 0.234176 0.015" condim="4" friction="0.25 0.005 0.0001" solref="0.01 1" solimp="0.95 0.95 0.01 0.5 2" rgba="1 1 1 1"/>
            <geom name="spheret30" size="5.47921e-05" pos="0.542088 -0.124545 0.015" condim="4" friction="0.25 0.005 0.0001" solref="0.01 1" solimp="0.95 0.95 0.01 0.5 2" rgba="1 1 1 1"/>
            <geom name="spheret31" size="0.000112333" pos="-0.470925 -0.286167 0.015" condim="4" friction="0.25 0.005 0.0001" solref="0.01 1" solimp="0.95 0.95 0.01 0.5 2" rgba="1 1 1 1"/>
            <geom name="spheret32" size="0.000154413" pos="-0.489129 -0.0981306 0.015" condim="4" friction="0.25 0.005 0.0001" solref="0.01 1" solimp="0.95 0.95 0.01 0.5 2" rgba="1 1 1 1"/>
            <geom name="spheret33" size="0.000173667" pos="-0.00117917 -0.101733 0.015" condim="4" friction="0.25 0.005 0.0001" solref="0.01 1" solimp="0.95 0.95 0.01 0.5 2" rgba="1 1 1 1"/>
            <geom name="spheret34" size="6.43555e-05" pos="-0.182492 -0.236159 0.015" condim="4" friction="0.25 0.005 0.0001" solref="0.01 1" solimp="0.95 0.95 0.01 0.5 2" rgba="1 1 1 1"/>
            <geom name="spheret35" size="7.28664e-05" pos="-0.560458 0.0222735 0.015" condim="4" friction="0.25 0.005 0.0001" solref="0.01 1" solimp="0.95 0.95 0.01 0.5 2" rgba="1 1 1 1"/>
            <geom name="spheret36" size="0.000112045" pos="0.0943364 0.284455 0.015" condim="4" friction="0.25 0.005 0.0001" solref="0.01 1" solimp="0.95 0.95 0.01 0.5 2" rgba="1 1 1 1"/>
            <geom name="spheret37" size="0.000189871" pos="0.408419 -0.139751 0.015" condim="4" friction="0.25 0.005 0.0001" solref="0.01 1" solimp="0.95 0.95 0.01 0.5 2" rgba="1 1 1 1"/>
            <geom name="spheret38" size="0.000104425" pos="-0.531417 0.204764 0.015" condim="4" friction="0.25 0.005 0.0001" solref="0.01 1" solimp="0.95 0.95 0.01 0.5 2" rgba="1 1 1 1"/>
            <geom name="spheret39" size="6.46463e-05" pos="-0.0807488 0.267109 0.015" condim="4" friction="0.25 0.005 0.0001" solref="0.01 1" solimp="0.95 0.95 0.01 0.5 2" rgba="1 1 1 1"/>
            <geom name="spheret40" size="0.000155711" pos="-0.455344 0.0763014 0.015" condim="4" friction="0.25 0.005 0.0001" solref="0.01 1" solimp="0.95 0.95 0.01 0.5 2" rgba="1 1 1 1"/>
            <geom name="spheret41" size="6.39697e-05" pos="0.493002 -0.0880871 0.015" condim="4" friction="0.25 0.005 0.0001" solref="0.01 1" solimp="0.95 0.95 0.01 0.5 2" rgba="1 1 1 1"/>
            <geom name="spheret42" size="6.64699e-05" pos="-0.449382 -0.225242 0.015" condim="4" friction="0.25 0.005 0.0001" solref="0.01 1" solimp="0.95 0.95 0.01 0.5 2" rgba="1 1 1 1"/>
            <geom name="spheret43" size="5.42485e-05" pos="-0.324701 0.291054 0.015" condim="4" friction="0.25 0.005 0.0001" solref="0.01 1" solimp="0.95 0.95 0.01 0.5 2" rgba="1 1 1 1"/>
            <geom name="spheret44" size="0.000171026" pos="0.5102 -0.122796 0.015" condim="4" friction="0.25 0.005 0.0001" solref="0.01 1" solimp="0.95 0.95 0.01 0.5 2" rgba="1 1 1 1"/>
            <geom name="spheret45" size="0.000178569" pos="-0.297155 -0.294762 0.015" condim="4" friction="0.25 0.005 0.0001" solref="0.01 1" solimp="0.95 0.95 0.01 0.5 2" rgba="1 1 1 1"/>
            <geom name="spheret46" size="0.000147971" pos="0.596273 0.160177 0.015" condim="4" friction="0.25 0.005 0.0001" solref="0.01 1" solimp="0.95 0.95 0.01 0.5 2" rgba="1 1 1 1"/>
            <geom name="spheret47" size="5.9237e-05" pos="-0.218896 0.0802522 0.015" condim="4" friction="0.25 0.005 0.0001" solref="0.01 1" solimp="0.95 0.95 0.01 0.5 2" rgba="1 1 1 1"/>
            <geom name="spheret48" size="6.85325e-05" pos="-0.454536 -0.201713 0.015" condim="4" friction="0.25 0.005 0.0001" solref="0.01 1" solimp="0.95 0.95 0.01 0.5 2" rgba="1 1 1 1"/>
            <geom name="spheret49" size="8.18393e-05" pos="-0.46675 0.185999 0.015" condim="4" friction="0.25 0.005 0.0001" solref="0.01 1" solimp="0.95 0.95 0.01 0.5 2" rgba="1 1 1 1"/>
            <geom name="spheret50" size="0.000100411" pos="-0.0419433 0.102844 0.015" condim="4" friction="0.25 0.005 0.0001" solref="0.01 1" solimp="0.95 0.95 0.01 0.5 2" rgba="1 1 1 1"/>
            <geom name="spheret51" size="0.000178493" pos="-0.350728 -0.291409 0.015" condim="4" friction="0.25 0.005 0.0001" solref="0.01 1" solimp="0.95 0.95 0.01 0.5 2" rgba="1 1 1 1"/>
            <geom name="spheret52" size="5.04174e-05" pos="-0.0982819 0.086597 0.015" condim="4" friction="0.25 0.005 0.0001" solref="0.01 1" solimp="0.95 0.95 0.01 0.5 2" rgba="1 1 1 1"/>
            <geom name="spheret53" size="7.55866e-05" pos="0.347769 -0.253054 0.015" condim="4" friction="0.25 0.005 0.0001" solref="0.01 1" solimp="0.95 0.95 0.01 0.5 2" rgba="1 1 1 1"/>
            <geom name="spheret54" size="8.19206e-05" pos="0.451315 -0.0718929 0.015" condim="4" friction="0.25 0.005 0.0001" solref="0.01 1" solimp="0.95 0.95 0.01 0.5 2" rgba="1 1 1 1"/>
            <geom name="spheret55" size="5.60454e-05" pos="0.516162 -0.264657 0.015" condim="4" friction="0.25 0.005 0.0001" solref="0.01 1" solimp="0.95 0.95 0.01 0.5 2" rgba="1 1 1 1"/>
            <geom name="spheret56" size="0.000153463" pos="-0.502391 -0.198604 0.015" condim="4" friction="0.25 0.005 0.0001" solref="0.01 1" solimp="0.95 0.95 0.01 0.5 2" rgba="1 1 1 1"/>
            <geom name="spheret57" size="0.000165079" pos="-0.310401 0.0105572 0.015" condim="4" friction="0.25 0.005 0.0001" solref="0.01 1" solimp="0.95 0.95 0.01 0.5 2" rgba="1 1 1 1"/>
            <geom name="spheret58" size="0.000119463" pos="0.401263 0.00683714 0.015" condim="4" friction="0.25 0.005 0.0001" solref="0.01 1" solimp="0.95 0.95 0.01 0.5 2" rgba="1 1 1 1"/>
            <geom name="spheret59" size="9.43298e-05" pos="-0.114013 -0.185441 0.015" condim="4" friction="0.25 0.005 0.0001" solref="0.01 1" solimp="0.95 0.95 0.01 0.5 2" rgba="1 1 1 1"/>
            <geom name="spheret60" size="0.000185583" pos="0.501942 0.184495 0.015" condim="4" friction="0.25 0.005 0.0001" solref="0.01 1" solimp="0.95 0.95 0.01 0.5 2" rgba="1 1 1 1"/>
            <geom name="spheret61" size="0.000176026" pos="0.479929 0.130815 0.015" condim="4" friction="0.25 0.005 0.0001" solref="0.01 1" solimp="0.95 0.95 0.01 0.5 2" rgba="1 1 1 1"/>
            <geom name="spheret62" size="0.000104267" pos="0.394142 0.186302 0.015" condim="4" friction="0.25 0.005 0.0001" solref="0.01 1" solimp="0.95 0.95 0.01 0.5 2" rgba="1 1 1 1"/>
            <geom name="spheret63" size="0.000170093" pos="-0.126678 0.267409 0.015" condim="4" friction="0.25 0.005 0.0001" solref="0.01 1" solimp="0.95 0.95 0.01 0.5 2" rgba="1 1 1 1"/>
            <geom name="spheret64" size="0.000194113" pos="-0.285377 -0.128628 0.015" condim="4" friction="0.25 0.005 0.0001" solref="0.01 1" solimp="0.95 0.95 0.01 0.5 2" rgba="1 1 1 1"/>
            <geom name="spheret65" size="0.000138366" pos="-0.130751 0.0121834 0.015" condim="4" friction="0.25 0.005 0.0001" solref="0.01 1" solimp="0.95 0.95 0.01 0.5 2" rgba="1 1 1 1"/>
            <geom name="spheret66" size="0.000194796" pos="0.157128 0.270304 0.015" condim="4" friction="0.25 0.005 0.0001" solref="0.01 1" solimp="0.95 0.95 0.01 0.5 2" rgba="1 1 1 1"/>
            <geom name="spheret67" size="0.000141027" pos="-0.118259 -0.155653 0.015" condim="4" friction="0.25 0.005 0.0001" solref="0.01 1" solimp="0.95 0.95 0.01 0.5 2" rgba="1 1 1 1"/>
            <geom name="spheret68" size="0.000137256" pos="0.235713 0.151991 0.015" condim="4" friction="0.25 0.005 0.0001" solref="0.01 1" solimp="0.95 0.95 0.01 0.5 2" rgba="1 1 1 1"/>
            <geom name="spheret69" size="0.000103882" pos="0.314564 0.00160368 0.015" condim="4" friction="0.25 0.005 0.0001" solref="0.01 1" solimp="0.95 0.95 0.01 0.5 2" rgba="1 1 1 1"/>
            <geom name="spheret70" size="8.20317e-05" pos="0.212634 0.0134379 0.015" condim="4" friction="0.25 0.005 0.0001" solref="0.01 1" solimp="0.95 0.95 0.01 0.5 2" rgba="1 1 1 1"/>
            <geom name="spheret71" size="9.53159e-05" pos="0.480241 -0.122641 0.015" condim="4" friction="0.25 0.005 0.0001" solref="0.01 1" solimp="0.95 0.95 0.01 0.5 2" rgba="1 1 1 1"/>
            <geom name="spheret72" size="0.000158633" pos="-0.42293 0.221908 0.015" condim="4" friction="0.25 0.005 0.0001" solref="0.01 1" solimp="0.95 0.95 0.01 0.5 2" rgba="1 1 1 1"/>
            <geom name="spheret73" size="0.000131693" pos="-0.252662 0.0694374 0.015" condim="4" friction="0.25 0.005 0.0001" solref="0.01 1" solimp="0.95 0.95 0.01 0.5 2" rgba="1 1 1 1"/>
            <geom name="spheret74" size="0.000128645" pos="-0.559388 0.0400818 0.015" condim="4" friction="0.25 0.005 0.0001" solref="0.01 1" solimp="0.95 0.95 0.01 0.5 2" rgba="1 1 1 1"/>
            <geom name="spheret75" size="9.9524e-05" pos="0.393923 -0.112455 0.015" condim="4" friction="0.25 0.005 0.0001" solref="0.01 1" solimp="0.95 0.95 0.01 0.5 2" rgba="1 1 1 1"/>
            <geom name="spheret76" size="6.00803e-05" pos="0.184563 -0.174069 0.015" condim="4" friction="0.25 0.005 0.0001" solref="0.01 1" solimp="0.95 0.95 0.01 0.5 2" rgba="1 1 1 1"/>
            <geom name="spheret77" size="0.000192454" pos="-0.235533 -0.278593 0.015" condim="4" friction="0.25 0.005 0.0001" solref="0.01 1" solimp="0.95 0.95 0.01 0.5 2" rgba="1 1 1 1"/>
            <geom name="spheret78" size="8.43512e-05" pos="0.270265 -0.101389 0.015" condim="4" friction="0.25 0.005 0.0001" solref="0.01 1" solimp="0.95 0.95 0.01 0.5 2" rgba="1 1 1 1"/>
            <geom name="spheret79" size="8.48262e-05" pos="0.267735 -0.226732 0.015" condim="4" friction="0.25 0.005 0.0001" solref="0.01 1" solimp="0.95 0.95 0.01 0.5 2" rgba="1 1 1 1"/>
            <geom name="spheret80" size="0.000157804" pos="-0.400235 -0.233141 0.015" condim="4" friction="0.25 0.005 0.0001" solref="0.01 1" solimp="0.95 0.95 0.01 0.5 2" rgba="1 1 1 1"/>
            <geom name="spheret81" size="9.98318e-05" pos="0.509338 -0.0793884 0.015" condim="4" friction="0.25 0.005 0.0001" solref="0.01 1" solimp="0.95 0.95 0.01 0.5 2" rgba="1 1 1 1"/>
            <geom name="spheret82" size="5.09714e-05" pos="0.221426 0.24734 0.015" condim="4" friction="0.25 0.005 0.0001" solref="0.01 1" solimp="0.95 0.95 0.01 0.5 2" rgba="1 1 1 1"/>
            <geom name="spheret83" size="0.0001975" pos="-0.488194 0.294579 0.015" condim="4" friction="0.25 0.005 0.0001" solref="0.01 1" solimp="0.95 0.95 0.01 0.5 2" rgba="1 1 1 1"/>
            <geom name="spheret84" size="0.000164612" pos="-0.209001 -0.150129 0.015" condim="4" friction="0.25 0.005 0.0001" solref="0.01 1" solimp="0.95 0.95 0.01 0.5 2" rgba="1 1 1 1"/>
            <geom name="spheret85" size="9.68139e-05" pos="0.371415 0.00707126 0.015" condim="4" friction="0.25 0.005 0.0001" solref="0.01 1" solimp="0.95 0.95 0.01 0.5 2" rgba="1 1 1 1"/>
            <geom name="spheret86" size="0.000174639" pos="-0.448184 0.271027 0.015" condim="4" friction="0.25 0.005 0.0001" solref="0.01 1" solimp="0.95 0.95 0.01 0.5 2" rgba="1 1 1 1"/>
            <geom name="spheret87" size="0.000134549" pos="-0.536748 -0.169425 0.015" condim="4" friction="0.25 0.005 0.0001" solref="0.01 1" solimp="0.95 0.95 0.01 0.5 2" rgba="1 1 1 1"/>
            <geom name="spheret88" size="0.000188708" pos="-0.342737 0.0176437 0.015" condim="4" friction="0.25 0.005 0.0001" solref="0.01 1" solimp="0.95 0.95 0.01 0.5 2" rgba="1 1 1 1"/>
            <geom name="spheret89" size="0.00019474" pos="0.335524 -0.0481993 0.015" condim="4" friction="0.25 0.005 0.0001" solref="0.01 1" solimp="0.95 0.95 0.01 0.5 2" rgba="1 1 1 1"/>
            <geom name="spheret90" size="0.00014589" pos="0.20431 0.110312 0.015" condim="4" friction="0.25 0.005 0.0001" solref="0.01 1" solimp="0.95 0.95 0.01 0.5 2" rgba="1 1 1 1"/>
            <geom name="spheret91" size="7.33049e-05" pos="0.188958 0.169462 0.015" condim="4" friction="0.25 0.005 0.0001" solref="0.01 1" solimp="0.95 0.95 0.01 0.5 2" rgba="1 1 1 1"/>
            <geom name="spheret92" size="0.000105885" pos="0.279643 -0.036055 0.015" condim="4" friction="0.25 0.005 0.0001" solref="0.01 1" solimp="0.95 0.95 0.01 0.5 2" rgba="1 1 1 1"/>
            <geom name="spheret93" size="0.000187431" pos="-0.224471 -0.156701 0.015" condim="4" friction="0.25 0.005 0.0001" solref="0.01 1" solimp="0.95 0.95 0.01 0.5 2" rgba="1 1 1 1"/>
            <geom name="spheret94" size="7.62441e-05" pos="-0.206177 -0.0677054 0.015" condim="4" friction="0.25 0.005 0.0001" solref="0.01 1" solimp="0.95 0.95 0.01 0.5 2" rgba="1 1 1 1"/>
            <geom name="spheret95" size="7.39978e-05" pos="-0.566064 0.0824928 0.015" condim="4" friction="0.25 0.005 0.0001" solref="0.01 1" solimp="0.95 0.95 0.01 0.5 2" rgba="1 1 1 1"/>
            <geom name="spheret96" size="7.7068e-05" pos="0.105274 0.135129 0.015" condim="4" friction="0.25 0.005 0.0001" solref="0.01 1" solimp="0.95 0.95 0.01 0.5 2" rgba="1 1 1 1"/>
            <geom name="spheret97" size="0.000140011" pos="0.404492 0.117939 0.015" condim="4" friction="0.25 0.005 0.0001" solref="0.01 1" solimp="0.95 0.95 0.01 0.5 2" rgba="1 1 1 1"/>
            <geom name="spheret98" size="0.000139549" pos="-0.553568 -0.151231 0.015" condim="4" friction="0.25 0.005 0.0001" solref="0.01 1" solimp="0.95 0.95 0.01 0.5 2" rgba="1 1 1 1"/>
            <geom name="spheret99" size="8.81167e-05" pos="0.364953 -0.275385 0.015" condim="4" friction="0.25 0.005 0.0001" solref="0.01 1" solimp="0.95 0.95 0.01 0.5 2" rgba="1 1 1 1"/>
            <site name="target0" pos="-0.1 -0.25 0.015" size="0.02 0.0001" type="cylinder" rgba="0 1 0 1"/>
        </body>
        <body name="ConSurf" pos="0.45 0 0.84">
            <joint name="object0:joint_x" pos="0 0 0" axis="1 0 0" type="slide" damping="0.01"/>
            <joint name="object0:joint_y" pos="0 0 0" axis="0 1 0" type="slide" damping="0.01"/>
            <joint name="object0:joint_z" pos="0 0 0" axis="0 0 1" type="slide" damping="0.01"/>
            <joint name="object0:joint_r" pos="0 0 0" axis="1 0 0" damping="0.01"/>
            <joint name="object0:joint_p" pos="0 0 0" axis="0 1 0" damping="0.01"/>
            <joint name="object0:joint_yw" pos="0 0 0" axis="0 0 1" damping="0.01"/>
            <geom name="ConSurf" size="0.035 0.015 0.025" type="box" priority="2" friction="0.45 0.005 0.0001" solref="0.01 1" solimp="0.95 0.95 0.01 0.5 2" rgba="0.999 0.999 0.999 1"/>
            <site name="object0" pos="0 0 -0.025" size="0.0001 0.0001" type="cylinder" rgba="0 1 0 1"/>
        </body>
    </worldbody>
    <equality>
        <tendon tendon1="gf1_t" polycoef="0 1 0 0 0" solref="0.01 1" solimp="0.99 0.99 0.001 0.5 2"/>
        <tendon tendon1="gf2_t" polycoef="0 1 0 0 0" solref="0.01 1" solimp="0.99 0.99 0.001 0.5 2"/>
    </equality>
    <tendon>
        <spatial name="gf1_t" stiffness="10" damping="0.2" width="2e-05" rgba="0.9 0.9 0.9 1">
            <site site="gf1a_s"/>
            <site site="gf1b_s"/>
        </spatial>
        <spatial name="gf2_t" stiffness="10" damping="0.2" width="2e-05" rgba="0.9 0.9 0.9 1">
            <site site="gf2a_s"/>
            <site site="gf2b_s"/>
        </spatial>
    </tendon>
    <actuator>
        <general name="Joint1" joint="robot0:joint_1" ctrllimited="true" ctrlrange="-39 39" gear="3 0 0 0 0 0"/>
        <general name="Joint2" joint="robot0:joint_2" ctrllimited="true" ctrlrange="-39 39" gear="3 0 0 0 0 0"/>
        <general name="Joint3" joint="robot0:joint_3" ctrllimited="true" ctrlrange="-39 39" gear="3 0 0 0 0 0"/>
        <general name="Joint4" joint="robot0:joint_4" ctrllimited="true" ctrlrange="-39 39" gear="3 0 0 0 0 0"/>
        <general name="Joint5" joint="robot0:joint_5" ctrllimited="true" ctrlrange="-19 19" gear="3 0 0 0 0 0"/>
        <general name="Joint6" joint="robot0:joint_6" ctrllimited="true" ctrlrange="-19 19" gear="3 0 0 0 0 0"/>
        <general name="Joint7" joint="robot0:joint_7" ctrllimited="true" ctrlrange="-19 19" gear="3 0 0 0 0 0"/>
        <general name="JointGL" joint="robot0:gripper_finger1_joint" ctrllimited="true" ctrlrange="0 1.5" forcerange="0 5" biastype="affine" gainprm="80 0 0 0 0 0 0 0 0 0" biasprm="0 -80 0 0 0 0 0 0 0 0"/>
        <general name="JointGR" joint="robot0:gripper_finger2_joint" ctrllimited="true" ctrlrange="0 1.5" forcerange="0 5" biastype="affine" gainprm="80 0 0 0 0 0 0 0 0 0" biasprm="0 -80 0 0 0 0 0 0 0 0"/>
    </actuator>
    <keyframe>
        <key time="3.4519999999998414" qpos="-0.07366123796746009 0.1853017383444345 -3.053517172143994 -1.9301102127867198 -0.017396065441452346 -1.0446874811358524 1.5903238583925596 -0.0012384395978404026 -0.0011142028676726146 -0.001168234720575119 0.005208318078793425 -0.0012387770082530351 -0.0011143350248440133 -0.001160060080265825 0.005191866942946578 0.0 0.0 -2.452499999999703e-05 0.0 0.0 0.0" qvel="1.1717812751275521e-05 3.27691431409689e-07 -1.2810676934988456e-05 4.3397217262301947e-07 5.644201356738952e-07 -1.4774117691960154e-07 -1.3034530842998818e-07 -4.253397299886525e-12 -4.311242825812153e-12 1.4237343396207057e-11 -1.3013799734413654e-11 4.200415473872247e-12 4.261747108020272e-12 -1.4405185183055242e-11 1.2907331642214694e-11 0.0 0.0 3.771824688414198e-16 0.0 0.0 0.0"/>
    </keyframe>
</mujoco>