<?xml version="1.0" ?>
<mujoco model="gen3_robotiq_2f_85">
    <compiler angle="radian" meshdir="gen3/"/>
    <option cone="elliptic"/>
    <size njmax="500" nconmax="500"/>
    <visual>
        <global offwidth="1920" offheight="1043"/>
    </visual>
    <default class="main">
        <default class="GEN3">
            <joint armature="0.01"/>
        </default>
        <default class="2F-85">
            <joint armature="0.08" damping="5"/>
        </default>
    </default>
    <asset>
        <texture type="2d" name="texplane" builtin="checker" mark="cross" rgb1="0.8 0.9 1" rgb2="0.6 0.8 0.8" markrgb="0.8 0.8 0.8" width="512" height="512"/>
        <material name="matplane" texture="texplane" texuniform="true" reflectance="0.3"/>
        <mesh name="base_link" file="base_link.STL"/>
        <mesh name="shoulder_link" file="shoulder_link.STL"/>
        <mesh name="half_arm_1_link" file="half_arm_1_link.STL"/>
        <mesh name="half_arm_2_link" file="half_arm_2_link.STL"/>
        <mesh name="forearm_link" file="forearm_link.STL"/>
        <mesh name="spherical_wrist_1_link" file="spherical_wrist_1_link.STL"/>
        <mesh name="spherical_wrist_2_link" file="spherical_wrist_2_link.STL"/>
        <mesh name="bracelet_link" file="bracelet_link.STL"/>
        <mesh name="robotiq_85_base_link" file="robotiq_85_base_link.stl"/>
        <mesh name="robotiq_85_knuckle_link" file="robotiq_85_knuckle_link.stl"/>
        <mesh name="robotiq_85_finger_link" file="robotiq_85_finger_link.stl"/>
        <mesh name="robotiq_85_inner_knuckle_link" file="robotiq_85_inner_knuckle_link.stl"/>
        <mesh name="robotiq_85_finger_tip_link" file="robotiq_85_finger_tip_link.stl"/>
    </asset>
    <worldbody>
        <geom size="0 0 0.1" type="plane" material="matplane"/>
        <light pos="0 0 100" dir="0 0 -1" castshadow="false" diffuse="0.5 0.5 0.5"/>
        <body name="top" pos="0 0 0">
            <camera name="realsense-top" pos="0.13 0 2.1" fovy="41"/>
        </body>
        <body name="front" pos="0 0 0">
            <camera name="realsense-front" pos="1.37 0 1.12" quat="0.500398 -0.5 0.5 -0.499602" fovy="41"/>
        </body>
        <body name="side-1" pos="0 0 0">
            <camera name="realsense-side-1" pos="0.13 1.5 1.12" quat="0.707388 -0.706825 0 0" fovy="41"/>
        </body>
        <body name="side-2" pos="0 0 0">
            <camera name="realsense-side-2" pos="0.13 -1.5 1.12" quat="0.000563312 0.000562864 -0.706825 0.707388" fovy="41"/>
        </body>
        <body name="Gen3_robot" pos="-0.07 0 0.82">
            <geom type="mesh" rgba="0.75294 0.75294 0.75294 1" mesh="base_link"/>
            <body name="shoulder_link" pos="0 0 0.15643" quat="-3.67321e-06 1 0 0">
                <joint name="robot0:joint_1" class="GEN3" pos="0 0 0" axis="0 0 1"/>
                <geom type="mesh" rgba="0.75294 0.75294 0.75294 1" mesh="shoulder_link"/>
                <body name="half_arm_1_link" pos="0 0.005375 -0.12838" quat="0.707105 0.707108 0 0">
                    <joint name="robot0:joint_2" class="GEN3" pos="0 0 0" axis="0 0 1" limited="true" range="-2.41 2.41"/>
                    <geom type="mesh" rgba="0.75294 0.75294 0.75294 1" mesh="half_arm_1_link"/>
                    <body name="half_arm_2_link" pos="0 -0.21038 -0.006375" quat="0.707105 -0.707108 0 0">
                        <joint name="robot0:joint_3" class="GEN3" pos="0 0 0" axis="0 0 1"/>
                        <geom type="mesh" rgba="0.75294 0.75294 0.75294 1" mesh="half_arm_2_link"/>
                        <body name="forearm_link" pos="0 0.006375 -0.21038" quat="0.707105 0.707108 0 0">
                            <joint name="robot0:joint_4" class="GEN3" pos="0 0 0" axis="0 0 1" limited="true" range="-2.66 2.66"/>
                            <geom type="mesh" rgba="0.75294 0.75294 0.75294 1" mesh="forearm_link"/>
                            <body name="spherical_wrist_1_link" pos="0 -0.20843 -0.006375" quat="0.707105 -0.707108 0 0">
                                <joint name="robot0:joint_5" class="GEN3" pos="0 0 0" axis="0 0 1"/>
                                <geom type="mesh" rgba="0.75294 0.75294 0.75294 1" mesh="spherical_wrist_1_link"/>
                                <body name="spherical_wrist_2_link" pos="0 0.00017505 -0.10593" quat="0.707105 0.707108 0 0">
                                    <joint name="robot0:joint_6" class="GEN3" pos="0 0 0" axis="0 0 1" limited="true" range="-2.23 2.23"/>
                                    <geom type="mesh" rgba="0.75294 0.75294 0.75294 1" mesh="spherical_wrist_2_link"/>
                                    <body name="bracelet_link" pos="0 -0.10593 -0.00017505" quat="0.707105 -0.707108 0 0">
                                        <joint name="robot0:joint_7" class="GEN3" pos="0 0 0" axis="0 0 1"/>
                                        <geom type="mesh" rgba="0.75294 0.75294 0.75294 1" mesh="bracelet_link"/>
                                        <geom pos="0 0 -0.061525" quat="-0.5 0.500398 -0.499602 -0.5" type="mesh" mesh="robotiq_85_base_link"/>
                                        <site name="robot0:0grip0" pos="0 0 -0.1" size="0.03" rgba="0 1 0 0"/>
                                        <site name="robot0:grip" pos="0 0 -0.21" size="0.01" rgba="0 1 0 0"/>
                                        <site name="gf1b_s" pos="-0.0126511 -1.01133e-05 -0.122955" size="0.002"/>
                                        <site name="gf2b_s" pos="0.0127489 1.01133e-05 -0.122935" size="0.002"/>
                                        <camera name="realsense" pos="0.0275 -0.066 -0.0585" fovy="41"/>
                                        <body name="gripper_finger1_knuckle_link" pos="-0.0305574 -2.43685e-05 -0.116454" quat="-0.500399 -0.499999 -0.500001 0.499601">
                                            <joint name="robot0:gripper_finger1_joint" class="2F-85" pos="0 0 0" axis="0 0 1" limited="true" range="0 0.804"/>
                                            <geom type="mesh" mesh="robotiq_85_knuckle_link"/>
                                            <body name="gripper_finger1_knuckle2_link" pos="0 0 0">
                                                <joint name="gripper_finger1_joint2" class="2F-85" pos="-0.00408552 -0.031486 0" axis="0 0 1" limited="true" range="0 0.804"/>
                                                <geom pos="-0.00408552 -0.031486 0" type="mesh" mesh="robotiq_85_finger_link"/>
                                                <body name="gripper_finger1_finger_tip_link" pos="0.05 -0.02 0">
                                                    <joint name="gripper_finger1_finger_tip_joint" class="2F-85" pos="-0.0066 -0.017245 0" axis="0 0 1" stiffness="50" range="0 0.804"/>
                                                    <geom type="mesh" condim="4" friction="0 0 0" solref="0.01 1" solimp="0.99 0.99 0.01 0.5 2" mesh="robotiq_85_finger_tip_link"/>
                                                    <geom name="tip_left_pivot" size="0.0018" pos="0.038 0.00925 0" condim="4" friction="1.2 0.005 0.0001" solref="0.01 1" solimp="0.99 0.99 0.01 0.5 2" rgba="0 0.7 0.1 1"/>
                                                    <geom name="tip_left_pivot_slip" size="0.0024" pos="0.038 0.00925 0" condim="4" friction="0.5 0.005 0.0001" solref="0.01 1" solimp="0.95 0.95 0.01 0.5 2" rgba="0 0.7 0.1 1"/>
                                                    <geom name="tip_left_rubber" size="0.019 0.001 0.011" pos="0.025 0.00925 0" type="box" condim="4" friction="1 0.08 0.0001" solref="0.01 1" solimp="0.98 0.98 0.01 0.5 6" rgba="1.5 0.7 0.1 1"/>
                                                    <body name="gripper_finger1_inner_knuckle_link" pos="-0.0430396 0.0375994 0">
                                                        <joint name="gripper_finger1_inner_knuckle_joint" class="2F-85" pos="0.0430396 -0.0375994 0" axis="0 0 1" limited="true" range="0 0.804"/>
                                                        <geom type="mesh" mesh="robotiq_85_inner_knuckle_link"/>
                                                        <site name="gf1a_s" pos="0 0 0" size="0.002" rgba="0.9 0.1 0.1 1"/>
                                                    </body>
                                                </body>
                                            </body>
                                        </body>
                                        <body name="gripper_finger2_knuckle_link" pos="0.0306448 2.43685e-05 -0.116405" quat="-0.5 0.500398 -0.499602 -0.5">
                                            <joint name="robot0:gripper_finger2_joint" class="2F-85" pos="0 0 0" axis="0 0 1" limited="true" range="0 0.804"/>
                                            <geom type="mesh" mesh="robotiq_85_knuckle_link"/>
                                            <body name="gripper_finger2_knuckle2_link" pos="0 0 0">
                                                <joint name="gripper_finger2_joint2" class="2F-85" pos="-0.00408552 -0.031486 0" axis="0 0 1" limited="true" range="0 0.804"/>
                                                <geom pos="-0.00408552 -0.031486 0" type="mesh" mesh="robotiq_85_finger_link"/>
                                                <body name="gripper_finger2_finger_tip_link" pos="0.05 -0.02 0">
                                                    <joint name="gripper_finger2_finger_tip_joint" class="2F-85" pos="-0.0066 -0.017245 0" axis="0 0 1" stiffness="50" range="0 0.804"/>
                                                    <geom type="mesh" condim="4" friction="0 0 0" solref="0.01 1" solimp="0.99 0.99 0.01 0.5 2" mesh="robotiq_85_finger_tip_link"/>
                                                    <geom name="tip_right_pivot" size="0.0018" pos="0.038 0.00925 0" condim="4" friction="1.2 0.01 0.0001" solref="0.01 1" solimp="0.99 0.99 0.01 0.5 2" rgba="0 0.7 0.1 1"/>
                                                    <geom name="tip_right_pivot_slip" size="0.0024" pos="0.038 0.00925 0" condim="4" friction="0.5 0.005 0.0001" solref="0.01 1" solimp="0.95 0.95 0.01 0.5 2" rgba="0 0.7 0.1 1"/>
                                                    <geom name="tip_right_rubber" size="0.019 0.001 0.011" pos="0.025 0.00925 0" type="box" condim="4" friction="1 0.08 0.0001" solref="0.01 1" solimp="0.98 0.98 0.01 0.5 6" rgba="1.5 0.7 0.1 1"/>
                                                    <body name="gripper_finger2_inner_knuckle_link" pos="-0.0430396 0.0375994 0">
                                                        <joint name="gripper_finger2_inner_knuckle_joint" class="2F-85" pos="0.0430396 -0.0375994 0" axis="0 0 1" limited="true" range="0 0.804"/>
                                                        <geom type="mesh" mesh="robotiq_85_inner_knuckle_link"/>
                                                        <site name="gf2a_s" pos="0 0 0" size="0.002" rgba="0.9 0.1 0.1 1"/>
                                                    </body>
                                                </body>
                                            </body>
                                        </body>
                                    </body>
                                </body>
                            </body>
                        </body>
                    </body>
                </body>
            </body>
        </body>
        <body name="Table" pos="0.475 0 0.8">
            <geom size="0.6 0.3 0.015" type="box" condim="4" friction="0.25 0.005 0.0001" solref="0.01 1" solimp="0.95 0.95 0.01 0.5 2" rgba="0.8 0.2 0.1 1"/>
            <geom size="0.0135 0.2" pos="-0.575 -0.275 -0.2" type="cylinder" rgba="0.8 0.2 0.1 1"/>
            <geom size="0.0135 0.2" pos="-0.575 0.275 -0.2" type="cylinder" rgba="0.8 0.2 0.1 1"/>
            <geom size="0.0135 0.2" pos="0.575 -0.275 -0.2" type="cylinder" rgba="0.8 0.2 0.1 1"/>
            <geom size="0.0135 0.2" pos="0.575 0.275 -0.2" type="cylinder" rgba="0.8 0.2 0.1 1"/>
            <geom name="spheret0" size="9.36641e-05" pos="-0.183832 -0.170929 0.015" condim="4" friction="0.25 0.005 0.0001" solref="0.01 1" solimp="0.95 0.95 0.01 0.5 2" rgba="1 1 1 1"/>
            <geom name="spheret1" size="9.83347e-05" pos="-0.43398 -0.0215205 0.015" condim="4" friction="0.25 0.005 0.0001" solref="0.01 1" solimp="0.95 0.95 0.01 0.5 2" rgba="1 1 1 1"/>
            <geom name="spheret2" size="0.000112661" pos="-0.570866 -0.217376 0.015" condim="4" friction="0.25 0.005 0.0001" solref="0.01 1" solimp="0.95 0.95 0.01 0.5 2" rgba="1 1 1 1"/>
            <geom name="spheret3" size="0.000144473" pos="0.365329 -0.112147 0.015" condim="4" friction="0.25 0.005 0.0001" solref="0.01 1" solimp="0.95 0.95 0.01 0.5 2" rgba="1 1 1 1"/>
            <geom name="spheret4" size="0.000165128" pos="0.446094 -0.175242 0.015" condim="4" friction="0.25 0.005 0.0001" solref="0.01 1" solimp="0.95 0.95 0.01 0.5 2" rgba="1 1 1 1"/>
            <geom name="spheret5" size="0.000149219" pos="-0.488746 -0.215868 0.015" condim="4" friction="0.25 0.005 0.0001" solref="0.01 1" solimp="0.95 0.95 0.01 0.5 2" rgba="1 1 1 1"/>
            <geom name="spheret6" size="9.90195e-05" pos="0.533396 0.2755 0.015" condim="4" friction="0.25 0.005 0.0001" solref="0.01 1" solimp="0.95 0.95 0.01 0.5 2" rgba="1 1 1 1"/>
            <geom name="spheret7" size="0.000123984" pos="-0.588414 -0.261655 0.015" condim="4" friction="0.25 0.005 0.0001" solref="0.01 1" solimp="0.95 0.95 0.01 0.5 2" rgba="1 1 1 1"/>
            <geom name="spheret8" size="0.000129972" pos="-0.357218 -0.288363 0.015" condim="4" friction="0.25 0.005 0.0001" solref="0.01 1" solimp="0.95 0.95 0.01 0.5 2" rgba="1 1 1 1"/>
            <geom name="spheret9" size="9.47347e-05" pos="0.0117842 -0.235245 0.015" condim="4" friction="0.25 0.005 0.0001" solref="0.01 1" solimp="0.95 0.95 0.01 0.5 2" rgba="1 1 1 1"/>
            <geom name="spheret10" size="8.03379e-05" pos="0.0130657 -0.275229 0.015" condim="4" friction="0.25 0.005 0.0001" solref="0.01 1" solimp="0.95 0.95 0.01 0.5 2" rgba="1 1 1 1"/>
            <geom name="spheret11" size="9.23915e-05" pos="-0.359289 0.0088951 0.015" condim="4" friction="0.25 0.005 0.0001" solref="0.01 1" solimp="0.95 0.95 0.01 0.5 2" rgba="1 1 1 1"/>
            <geom name="spheret12" size="8.59472e-05" pos="0.307832 0.00953326 0.015" condim="4" friction="0.25 0.005 0.0001" solref="0.01 1" solimp="0.95 0.95 0.01 0.5 2" rgba="1 1 1 1"/>
            <geom name="spheret13" size="0.000197253" pos="-0.326804 0.29348 0.015" condim="4" friction="0.25 0.005 0.0001" solref="0.01 1" solimp="0.95 0.95 0.01 0.5 2" rgba="1 1 1 1"/>
            <geom name="spheret14" size="0.000161967" pos="-0.48433 -0.0494214 0.015" condim="4" friction="0.25 0.005 0.0001" solref="0.01 1" solimp="0.95 0.95 0.01 0.5 2" rgba="1 1 1 1"/>
            <geom name="spheret15" size="0.000147945" pos="-0.332242 0.165336 0.015" condim="4" friction="0.25 0.005 0.0001" solref="0.01 1" solimp="0.95 0.95 0.01 0.5 2" rgba="1 1 1 1"/>
            <geom name="spheret16" size="7.41088e-05" pos="-0.119653 0.18817 0.015" condim="4" friction="0.25 0.005 0.0001" solref="0.01 1" solimp="0.95 0.95 0.01 0.5 2" rgba="1 1 1 1"/>
            <geom name="spheret17" size="7.87967e-05" pos="-0.410248 0.0719394 0.015" condim="4" friction="0.25 0.005 0.0001" solref="0.01 1" solimp="0.95 0.95 0.01 0.5 2" rgba="1 1 1 1"/>
            <geom name="spheret18" size="0.000198814" pos="-0.364462 -0.0830993 0.015" condim="4" friction="0.25 0.005 0.0001" solref="0.01 1" solimp="0.95 0.95 0.01 0.5 2" rgba="1 1 1 1"/>
            <geom name="spheret19" size="7.2536e-05" pos="0.317977 -0.108767 0.015" condim="4" friction="0.25 0.005 0.0001" solref="0.01 1" solimp="0.95 0.95 0.01 0.5 2" rgba="1 1 1 1"/>
            <geom name="spheret20" size="0.000143337" pos="0.338643 0.164151 0.015" condim="4" friction="0.25 0.005 0.0001" solref="0.01 1" solimp="0.95 0.95 0.01 0.5 2" rgba="1 1 1 1"/>
            <geom name="spheret21" size="0.000131938" pos="-0.110399 0.0633552 0.015" condim="4" friction="0.25 0.005 0.0001" solref="0.01 1" solimp="0.95 0.95 0.01 0.5 2" rgba="1 1 1 1"/>
            <geom name="spheret22" size="0.000123796" pos="0.207204 0.203267 0.015" condim="4" friction="0.25 0.005 0.0001" solref="0.01 1" solimp="0.95 0.95 0.01 0.5 2" rgba="1 1 1 1"/>
            <geom name="spheret23" size="0.000193103" pos="-0.214103 -0.0366971 0.015" condim="4" friction="0.25 0.005 0.0001" solref="0.01 1" solimp="0.95 0.95 0.01 0.5 2" rgba="1 1 1 1"/>
            <geom name="spheret24" size="5.23377e-05" pos="-0.0232231 -0.130942 0.015" condim="4" friction="0.25 0.005 0.0001" solref="0.01 1" solimp="0.95 0.95 0.01 0.5 2" rgba="1 1 1 1"/>
            <geom name="spheret25" size="7.31701e-05" pos="-0.450353 0.0657477 0.015" condim="4" friction="0.25 0.005 0.0001" solref="0.01 1" solimp="0.95 0.95 0.01 0.5 2" rgba="1 1 1 1"/>
            <geom name="spheret26" size="0.000135155" pos="0.368903 -0.252382 0.015" condim="4" friction="0.25 0.005 0.0001" solref="0.01 1" solimp="0.95 0.95 0.01 0.5 2" rgba="1 1 1 1"/>
            <geom name="spheret27" size="6.34032e-05" pos="-0.126151 -0.158819 0.015" condim="4" friction="0.25 0.005 0.0001" solref="0.01 1" solimp="0.95 0.95 0.01 0.5 2" rgba="1 1 1 1"/>
            <geom name="spheret28" size="0.000143578" pos="-0.220711 0.0887011 0.015" condim="4" friction="0.25 0.005 0.0001" solref="0.01 1" solimp="0.95 0.95 0.01 0.5 2" rgba="1 1 1 1"/>
            <geom name="spheret29" size="7.48695e-05" pos="0.493643 0.268656 0.015" condim="4" friction="0.25 0.005 0.0001" solref="0.01 1" solimp="0.95 0.95 0.01 0.5 2" rgba="1 1 1 1"/>
            <geom name="spheret30" size="0.000128911" pos="-0.220856 -0.133281 0.015" condim="4" friction="0.25 0.005 0.0001" solref="0.01 1" solimp="0.95 0.95 0.01 0.5 2" rgba="1 1 1 1"/>
            <geom name="spheret31" size="5.0985e-05" pos="-0.157339 0.0902501 0.015" condim="4" friction="0.25 0.005 0.0001" solref="0.01 1" solimp="0.95 0.95 0.01 0.5 2" rgba="1 1 1 1"/>
            <geom name="spheret32" size="0.000146336" pos="-0.387496 -0.0838603 0.015" condim="4" friction="0.25 0.005 0.0001" solref="0.01 1" solimp="0.95 0.95 0.01 0.5 2" rgba="1 1 1 1"/>
            <geom name="spheret33" size="6.1162e-05" pos="-0.223203 -0.276659 0.015" condim="4" friction="0.25 0.005 0.0001" solref="0.01 1" solimp="0.95 0.95 0.01 0.5 2" rgba="1 1 1 1"/>
            <geom name="spheret34" size="6.3226e-05" pos="0.423958 0.211533 0.015" condim="4" friction="0.25 0.005 0.0001" solref="0.01 1" solimp="0.95 0.95 0.01 0.5 2" rgba="1 1 1 1"/>
            <geom name="spheret35" size="0.000177465" pos="-0.579023 0.183449 0.015" condim="4" friction="0.25 0.005 0.0001" solref="0.01 1" solimp="0.95 0.95 0.01 0.5 2" rgba="1 1 1 1"/>
            <geom name="spheret36" size="0.000122936" pos="-0.273626 -0.225209 0.015" condim="4" friction="0.25 0.005 0.0001" solref="0.01 1" solimp="0.95 0.95 0.01 0.5 2" rgba="1 1 1 1"/>
            <geom name="spheret37" size="0.000114204" pos="-0.333409 0.0854131 0.015" condim="4" friction="0.25 0.005 0.0001" solref="0.01 1" solimp="0.95 0.95 0.01 0.5 2" rgba="1 1 1 1"/>
            <geom name="spheret38" size="0.000102077" pos="0.135919 0.198722 0.015" condim="4" friction="0.25 0.005 0.0001" solref="0.01 1" solimp="0.95 0.95 0.01 0.5 2" rgba="1 1 1 1"/>
            <geom name="spheret39" size="0.000169046" pos="-0.11912 -0.112175 0.015" condim="4" friction="0.25 0.005 0.0001" solref="0.01 1" solimp="0.95 0.95 0.01 0.5 2" rgba="1 1 1 1"/>
            <geom name="spheret40" size="7.33674e-05" pos="0.143806 0.170979 0.015" condim="4" friction="0.25 0.005 0.0001" solref="0.01 1" solimp="0.95 0.95 0.01 0.5 2" rgba="1 1 1 1"/>
            <geom name="spheret41" size="0.000123219" pos="0.0410019 0.26926 0.015" condim="4" friction="0.25 0.005 0.0001" solref="0.01 1" solimp="0.95 0.95 0.01 0.5 2" rgba="1 1 1 1"/>
            <geom name="spheret42" size="0.000130892" pos="0.398969 -0.0218041 0.015" condim="4" friction="0.25 0.005 0.0001" solref="0.01 1" solimp="0.95 0.95 0.01 0.5 2" rgba="1 1 1 1"/>
            <geom name="spheret43" size="0.000131578" pos="0.304162 0.113908 0.015" condim="4" friction="0.25 0.005 0.0001" solref="0.01 1" solimp="0.95 0.95 0.01 0.5 2" rgba="1 1 1 1"/>
            <geom name="spheret44" size="6.27024e-05" pos="-0.522426 -0.133842 0.015" condim="4" friction="0.25 0.005 0.0001" solref="0.01 1" solimp="0.95 0.95 0.01 0.5 2" rgba="1 1 1 1"/>
            <geom name="spheret45" size="0.000143849" pos="0.278293 -0.205935 0.015" condim="4" friction="0.25 0.005 0.0001" solref="0.01 1" solimp="0.95 0.95 0.01 0.5 2" rgba="1 1 1 1"/>
            <geom name="spheret46" size="0.000159208" pos="0.173033 -0.065717 0.015" condim="4" friction="0.25 0.005 0.0001" solref="0.01 1" solimp="0.95 0.95 0.01 0.5 2" rgba="1 1 1 1"/>
            <geom name="spheret47" size="7.91683e-05" pos="-0.262368 -0.110444 0.015" condim="4" friction="0.25 0.005 0.0001" solref="0.01 1" solimp="0.95 0.95 0.01 0.5 2" rgba="1 1 1 1"/>
            <geom name="spheret48" size="0.000150799" pos="-0.0956159 0.0161436 0.015" condim="4" friction="0.25 0.005 0.0001" solref="0.01 1" solimp="0.95 0.95 0.01 0.5 2" rgba="1 1 1 1"/>
            <geom name="spheret49" size="5.92171e-05" pos="-0.29966 0.0193024 0.015" condim="4" friction="0.25 0.005 0.0001" solref="0.01 1" solimp="0.95 0.95 0.01 0.5 2" rgba="1 1 1 1"/>
            <geom name="spheret50" size="6.01234e-05" pos="0.597888 -0.204944 0.015" condim="4" friction="0.25 0.005 0.0001" solref="0.01 1" solimp="0.95 0.95 0.01 0.5 2" rgba="1 1 1 1"/>
            <geom name="spheret51" size="5.3272e-05" pos="-0.499977 0.218298 0.015" condim="4" friction="0.25 0.005 0.0001" solref="0.01 1" solimp="0.95 0.95 0.01 0.5 2" rgba="1 1 1 1"/>
            <geom name="spheret52" size="0.000187911" pos="0.0419061 -0.133269 0.015" condim="4" friction="0.25 0.005 0.0001" solref="0.01 1" solimp="0.95 0.95 0.01 0.5 2" rgba="1 1 1 1"/>
            <geom name="spheret53" size="8.88228e-05" pos="0.299607 -0.230021 0.015" condim="4" friction="0.25 0.005 0.0001" solref="0.01 1" solimp="0.95 0.95 0.01 0.5 2" rgba="1 1 1 1"/>
            <geom name="spheret54" size="9.98627e-05" pos="-0.215536 -0.246412 0.015" condim="4" friction="0.25 0.005 0.0001" solref="0.01 1" solimp="0.95 0.95 0.01 0.5 2" rgba="1 1 1 1"/>
            <geom name="spheret55" size="8.11229e-05" pos="0.030101 -0.219175 0.015" condim="4" friction="0.25 0.005 0.0001" solref="0.01 1" solimp="0.95 0.95 0.01 0.5 2" rgba="1 1 1 1"/>
            <geom name="spheret56" size="0.00010249" pos="-0.332366 -0.0451549 0.015" condim="4" friction="0.25 0.005 0.0001" solref="0.01 1" solimp="0.95 0.95 0.01 0.5 2" rgba="1 1 1 1"/>
            <geom name="spheret57" size="0.000170578" pos="-0.00248864 0.287846 0.015" condim="4" friction="0.25 0.005 0.0001" solref="0.01 1" solimp="0.95 0.95 0.01 0.5 2" rgba="1 1 1 1"/>
            <geom name="spheret58" size="0.000121717" pos="0.352768 -0.285439 0.015" condim="4" friction="0.25 0.005 0.0001" solref="0.01 1" solimp="0.95 0.95 0.01 0.5 2" rgba="1 1 1 1"/>
            <geom name="spheret59" size="0.000155647" pos="-0.427453 0.0944977 0.015" condim="4" friction="0.25 0.005 0.0001" solref="0.01 1" solimp="0.95 0.95 0.01 0.5 2" rgba="1 1 1 1"/>
            <geom name="spheret60" size="9.10358e-05" pos="-0.224827 -0.164907 0.015" condim="4" friction="0.25 0.005 0.0001" solref="0.01 1" solimp="0.95 0.95 0.01 0.5 2" rgba="1 1 1 1"/>
            <geom name="spheret61" size="6.60368e-05" pos="0.217071 0.2412 0.015" condim="4" friction="0.25 0.005 0.0001" solref="0.01 1" solimp="0.95 0.95 0.01 0.5 2" rgba="1 1 1 1"/>
            <geom name="spheret62" size="0.000138326" pos="-0.138001 0.14418 0.015" condim="4" friction="0.25 0.005 0.0001" solref="0.01 1" solimp="0.95 0.95 0.01 0.5 2" rgba="1 1 1 1"/>
            <geom name="spheret63" size="0.000123756" pos="-0.535395 0.175755 0.015" condim="4" friction="0.25 0.005 0.0001" solref="0.01 1" solimp="0.95 0.95 0.01 0.5 2" rgba="1 1 1 1"/>
            <geom name="spheret64" size="8.76855e-05" pos="-0.499934 -0.110003 0.015" condim="4" friction="0.25 0.005 0.0001" solref="0.01 1" solimp="0.95 0.95 0.01 0.5 2" rgba="1 1 1 1"/>
            <geom name="spheret65" size="0.000127219" pos="-0.216466 0.280509 0.015" condim="4" friction="0.25 0.005 0.0001" solref="0.01 1" solimp="0.95 0.95 0.01 0.5 2" rgba="1 1 1 1"/>
            <geom name="spheret66" size="5.82498e-05" pos="0.0243528 -0.0121441 0.015" condim="4" friction="0.25 0.005 0.0001" solref="0.01 1" solimp="0.95 0.95 0.01 0.5 2" rgba="1 1 1 1"/>
            <geom name="spheret67" size="0.000103856" pos="0.570779 0.186198 0.015" condim="4" friction="0.25 0.005 0.0001" solref="0.01 1" solimp="0.95 0.95 0.01 0.5 2" rgba="1 1 1 1"/>
            <geom name="spheret68" size="0.000154548" pos="-0.290349 0.154455 0.015" condim="4" friction="0.25 0.005 0.0001" solref="0.01 1" solimp="0.95 0.95 0.01 0.5 2" rgba="1 1 1 1"/>
            <geom name="spheret69" size="0.000106698" pos="0.238247 -0.289659 0.015" condim="4" friction="0.25 0.005 0.0001" solref="0.01 1" solimp="0.95 0.95 0.01 0.5 2" rgba="1 1 1 1"/>
            <geom name="spheret70" size="0.000186024" pos="0.0706266 0.11149 0.015" condim="4" friction="0.25 0.005 0.0001" solref="0.01 1" solimp="0.95 0.95 0.01 0.5 2" rgba="1 1 1 1"/>
            <geom name="spheret71" size="6.822e-05" pos="-0.00775931 -0.225781 0.015" condim="4" friction="0.25 0.005 0.0001" solref="0.01 1" solimp="0.95 0.95 0.01 0.5 2" rgba="1 1 1 1"/>
            <geom name="spheret72" size="0.000151586" pos="-0.533699 0.022618 0.015" condim="4" friction="0.25 0.005 0.0001" solref="0.01 1" solimp="0.95 0.95 0.01 0.5 2" rgba="1 1 1 1"/>
            <geom name="spheret73" size="0.000183298" pos="-0.541462 -0.218081 0.015" condim="4" friction="0.25 0.005 0.0001" solref="0.01 1" solimp="0.95 0.95 0.01 0.5 2" rgba="1 1 1 1"/>
            <geom name="spheret74" size="0.000173931" pos="0.326021 0.0610456 0.015" condim="4" friction="0.25 0.005 0.0001" solref="0.01 1" solimp="0.95 0.95 0.01 0.5 2" rgba="1 1 1 1"/>
            <geom name="spheret75" size="7.6854e-05" pos="0.312481 -0.110355 0.015" condim="4" friction="0.25 0.005 0.0001" solref="0.01 1" solimp="0.95 0.95 0.01 0.5 2" rgba="1 1 1 1"/>
            <geom name="spheret76" size="0.000144904" pos="0.249968 0.0961169 0.015" condim="4" friction="0.25 0.005 0.0001" solref="0.01 1" solimp="0.95 0.95 0.01 0.5 2" rgba="1 1 1 1"/>
            <geom name="spheret77" size="0.000165918" pos="0.165398 -0.121505 0.015" condim="4" friction="0.25 0.005 0.0001" solref="0.01 1" solimp="0.95 0.95 0.01 0.5 2" rgba="1 1 1 1"/>
            <geom name="spheret78" size="0.000153261" pos="-0.274223 -0.0940829 0.015" condim="4" friction="0.25 0.005 0.0001" solref="0.01 1" solimp="0.95 0.95 0.01 0.5 2" rgba="1 1 1 1"/>
            <geom name="spheret79" size="0.000185145" pos="-0.045417 -0.132163 0.015" condim="4" friction="0.25 0.005 0.0001" solref="0.01 1" solimp="0.95 0.95 0.01 0.5 2" rgba="1 1 1 1"/>
            <geom name="spheret80" size="8.83981e-05" pos="0.357313 -0.248736 0.015" condim="4" friction="0.25 0.005 0.0001" solref="0.01 1" solimp="0.95 0.95 0.01 0.5 2" rgba="1 1 1 1"/>
            <geom name="spheret81" size="0.000103449" pos="0.396829 0.109898 0.015" condim="4" friction="0.25 0.005 0.0001" solref="0.01 1" solimp="0.95 0.95 0.01 0.5 2" rgba="1 1 1 1"/>
            <geom name="spheret82" size="0.000121084" pos="0.387514 -0.0637825 0.015" condim="4" friction="0.25 0.005 0.0001" solref="0.01 1" solimp="0.95 0.95 0.01 0.5 2" rgba="1 1 1 1"/>
            <geom name="spheret83" size="0.000155445" pos="0.537462 0.1719 0.015" condim="4" friction="0.25 0.005 0.0001" solref="0.01 1" solimp="0.95 0.95 0.01 0.5 2" rgba="1 1 1 1"/>
            <geom name="spheret84" size="0.0001868" pos="-0.384131 -0.000159344 0.015" condim="4" friction="0.25 0.005 0.0001" solref="0.01 1" solimp="0.95 0.95 0.01 0.5 2" rgba="1 1 1 1"/>
            <geom name="spheret85" size="7.87979e-05" pos="-0.388369 0.127686 0.015" condim="4" friction="0.25 0.005 0.0001" solref="0.01 1" solimp="0.95 0.95 0.01 0.5 2" rgba="1 1 1 1"/>
            <geom name="spheret86" size="6.0935e-05" pos="0.577824 -0.149331 0.015" condim="4" friction="0.25 0.005 0.0001" solref="0.01 1" solimp="0.95 0.95 0.01 0.5 2" rgba="1 1 1 1"/>
            <geom name="spheret87" size="7.85852e-05" pos="0.363594 0.0438184 0.015" condim="4" friction="0.25 0.005 0.0001" solref="0.01 1" solimp="0.95 0.95 0.01 0.5 2" rgba="1 1 1 1"/>
            <geom name="spheret88" size="0.000148655" pos="-0.177101 -0.268054 0.015" condim="4" friction="0.25 0.005 0.0001" solref="0.01 1" solimp="0.95 0.95 0.01 0.5 2" rgba="1 1 1 1"/>
            <geom name="spheret89" size="8.25841e-05" pos="0.400856 -0.21811 0.015" condim="4" friction="0.25 0.005 0.0001" solref="0.01 1" solimp="0.95 0.95 0.01 0.5 2" rgba="1 1 1 1"/>
            <geom name="spheret90" size="0.000189788" pos="0.352614 -0.223927 0.015" condim="4" friction="0.25 0.005 0.0001" solref="0.01 1" solimp="0.95 0.95 0.01 0.5 2" rgba="1 1 1 1"/>
            <geom name="spheret91" size="0.000159989" pos="-0.359752 0.118635 0.015" condim="4" friction="0.25 0.005 0.0001" solref="0.01 1" solimp="0.95 0.95 0.01 0.5 2" rgba="1 1 1 1"/>
            <geom name="spheret92" size="0.000116818" pos="0.121282 -0.1633 0.015" condim="4" friction="0.25 0.005 0.0001" solref="0.01 1" solimp="0.95 0.95 0.01 0.5 2" rgba="1 1 1 1"/>
            <geom name="spheret93" size="7.6657e-05" pos="0.329977 0.175793 0.015" condim="4" friction="0.25 0.005 0.0001" solref="0.01 1" solimp="0.95 0.95 0.01 0.5 2" rgba="1 1 1 1"/>
            <geom name="spheret94" size="0.000198951" pos="-0.581954 0.18215 0.015" condim="4" friction="0.25 0.005 0.0001" solref="0.01 1" solimp="0.95 0.95 0.01 0.5 2" rgba="1 1 1 1"/>
            <geom name="spheret95" size="0.00018451" pos="-0.558886 0.10569 0.015" condim="4" friction="0.25 0.005 0.0001" solref="0.01 1" solimp="0.95 0.95 0.01 0.5 2" rgba="1 1 1 1"/>
            <geom name="spheret96" size="5.50841e-05" pos="0.133414 0.0635313 0.015" condim="4" friction="0.25 0.005 0.0001" solref="0.01 1" solimp="0.95 0.95 0.01 0.5 2" rgba="1 1 1 1"/>
            <geom name="spheret97" size="5.24891e-05" pos="0.291545 0.195892 0.015" condim="4" friction="0.25 0.005 0.0001" solref="0.01 1" solimp="0.95 0.95 0.01 0.5 2" rgba="1 1 1 1"/>
            <geom name="spheret98" size="0.000109533" pos="0.206988 -0.285681 0.015" condim="4" friction="0.25 0.005 0.0001" solref="0.01 1" solimp="0.95 0.95 0.01 0.5 2" rgba="1 1 1 1"/>
            <geom name="spheret99" size="6.04993e-05" pos="-0.343064 -0.0952148 0.015" condim="4" friction="0.25 0.005 0.0001" solref="0.01 1" solimp="0.95 0.95 0.01 0.5 2" rgba="1 1 1 1"/>
            <site name="target0" pos="-0.1 -0.25 0.015" size="0.02 0.0001" type="cylinder" rgba="0 1 0 1"/>
        </body>
        <body name="ConSurf" pos="0.45 0 0.84">
            <joint name="object0:joint_x" pos="0 0 0" axis="1 0 0" type="slide" damping="0.01"/>
            <joint name="object0:joint_y" pos="0 0 0" axis="0 1 0" type="slide" damping="0.01"/>
            <joint name="object0:joint_z" pos="0 0 0" axis="0 0 1" type="slide" damping="0.01"/>
            <joint name="object0:joint_r" pos="0 0 0" axis="1 0 0" damping="0.01"/>
            <joint name="object0:joint_p" pos="0 0 0" axis="0 1 0" damping="0.01"/>
            <joint name="object0:joint_yw" pos="0 0 0" axis="0 0 1" damping="0.01"/>
            <geom name="ConSurf" size="0.035 0.015 0.025" type="box" priority="2" friction="0.45 0.005 0.0001" solref="0.01 1" solimp="0.95 0.95 0.01 0.5 2" rgba="0.999 0.999 0.999 1"/>
            <site name="object0" pos="0 0 -0.025" size="0.0001 0.0001" type="cylinder" rgba="0 1 0 1"/>
        </body>
    </worldbody>
    <equality>
        <tendon tendon1="gf1_t" polycoef="0 1 0 0 0" solref="0.01 1" solimp="0.99 0.99 0.001 0.5 2"/>
        <tendon tendon1="gf2_t" polycoef="0 1 0 0 0" solref="0.01 1" solimp="0.99 0.99 0.001 0.5 2"/>
    </equality>
    <tendon>
        <spatial name="gf1_t" stiffness="10" damping="0.2" width="2e-05" rgba="0.9 0.9 0.9 1">
            <site site="gf1a_s"/>
            <site site="gf1b_s"/>
        </spatial>
        <spatial name="gf2_t" stiffness="10" damping="0.2" width="2e-05" rgba="0.9 0.9 0.9 1">
            <site site="gf2a_s"/>
            <site site="gf2b_s"/>
        </spatial>
    </tendon>
    <actuator>
        <general name="Joint1" joint="robot0:joint_1" ctrllimited="true" ctrlrange="-39 39" gear="3 0 0 0 0 0"/>
        <general name="Joint2" joint="robot0:joint_2" ctrllimited="true" ctrlrange="-39 39" gear="3 0 0 0 0 0"/>
        <general name="Joint3" joint="robot0:joint_3" ctrllimited="true" ctrlrange="-39 39" gear="3 0 0 0 0 0"/>
        <general name="Joint4" joint="robot0:joint_4" ctrllimited="true" ctrlrange="-39 39" gear="3 0 0 0 0 0"/>
        <general name="Joint5" joint="robot0:joint_5" ctrllimited="true" ctrlrange="-19 19" gear="3 0 0 0 0 0"/>
        <general name="Joint6" joint="robot0:joint_6" ctrllimited="true" ctrlrange="-19 19" gear="3 0 0 0 0 0"/>
        <general name="Joint7" joint="robot0:joint_7" ctrllimited="true" ctrlrange="-19 19" gear="3 0 0 0 0 0"/>
        <general name="JointGL" joint="robot0:gripper_finger1_joint" ctrllimited="true" ctrlrange="0 1.5" forcerange="0 5" biastype="affine" gainprm="80 0 0 0 0 0 0 0 0 0" biasprm="0 -80 0 0 0 0 0 0 0 0"/>
        <general name="JointGR" joint="robot0:gripper_finger2_joint" ctrllimited="true" ctrlrange="0 1.5" forcerange="0 5" biastype="affine" gainprm="80 0 0 0 0 0 0 0 0 0" biasprm="0 -80 0 0 0 0 0 0 0 0"/>
    </actuator>
    <keyframe>
        <key time="15.358000000001798" qpos="-0.07352172750814831 0.18530564054005855 -3.053669694215987 -1.9301050467855354 -0.017389345117768813 -1.0446892383869832 1.5903223064895269 -0.0012384396483090727 -0.0011142029186425343 -0.0011682345456501715 0.005208317927857135 -0.0012387769582054566 -0.0011143349739904166 -0.0011600602543495424 0.0051918670931501 0.0 0.0 -2.452499999999796e-05 0.0 0.0 0.0" qvel="1.1717507177435786e-05 3.278092410304116e-07 -1.2810366604101063e-05 4.338258001098384e-07 5.644768246044589e-07 -1.4744636582583048e-07 -1.3034729113413618e-07 -4.218894499055835e-12 -4.238950811220227e-12 1.518053495208428e-11 -1.2468656739648972e-11 4.206921310262444e-12 4.278682569544089e-12 -1.4575604260864546e-11 1.2592922440497368e-11 0.0 0.0 3.1798185050290075e-16 0.0 0.0 0.0"/>
    </keyframe>
</mujoco>