<?xml version="1.0" ?>
<mujoco model="gen3_robotiq_2f_85">
    <compiler angle="radian" meshdir="gen3/"/>
    <option cone="elliptic"/>
    <size njmax="500" nconmax="500"/>
    <visual>
        <global offwidth="1920" offheight="1043"/>
    </visual>
    <default class="main">
        <default class="GEN3">
            <joint armature="0.01"/>
        </default>
        <default class="2F-85">
            <joint armature="0.08" damping="5"/>
        </default>
        <default class="drawer_base">
            <joint armature="0.001" damping="2" limited="true"/>
            <geom conaffinity="0" contype="0" group="1" type="mesh"/>
            <position ctrllimited="true" ctrlrange="0 1.57"/>
            <default class="drawer_viz">
                <geom condim="4" type="mesh"/>
            </default>
            <default class="drawer_col">
                <geom conaffinity="1" condim="3" contype="1" group="4" material="drawer_col" solimp="0.99 0.99 0.01" solref="0.01 1"/>
            </default>
        </default>
    </default>
    <asset>
        <texture type="2d" name="texplane" builtin="checker" mark="cross" rgb1="0.8 0.9 1" rgb2="0.6 0.8 0.8" markrgb="0.8 0.8 0.8" width="512" height="512"/>
        <material name="matplane" texture="texplane" texuniform="true" reflectance="0.3"/>
        <mesh name="base_link" file="base_link.STL"/>
        <mesh name="shoulder_link" file="shoulder_link.STL"/>
        <mesh name="half_arm_1_link" file="half_arm_1_link.STL"/>
        <mesh name="half_arm_2_link" file="half_arm_2_link.STL"/>
        <mesh name="forearm_link" file="forearm_link.STL"/>
        <mesh name="spherical_wrist_1_link" file="spherical_wrist_1_link.STL"/>
        <mesh name="spherical_wrist_2_link" file="spherical_wrist_2_link.STL"/>
        <mesh name="bracelet_link" file="bracelet_link.STL"/>
        <mesh name="robotiq_85_base_link" file="robotiq_85_base_link.stl"/>
        <mesh name="robotiq_85_knuckle_link" file="robotiq_85_knuckle_link.stl"/>
        <mesh name="robotiq_85_finger_link" file="robotiq_85_finger_link.stl"/>
        <mesh name="robotiq_85_inner_knuckle_link" file="robotiq_85_inner_knuckle_link.stl"/>
        <mesh name="robotiq_85_finger_tip_link" file="robotiq_85_finger_tip_link.stl"/>
        
        <!-- Drawer -->
        <material name="drawer_col" rgba="0.3 0.3 1.0 0.5" shininess="0" specular="0"/>
        <material name="drawer_red" rgba="0.19 0.38 0.2 1" shininess="1" reflectance=".7" specular=".5"/>
        <material name="drawer_white" rgba=".75 .75 .75 1" shininess="1" reflectance=".7" specular=".5"/>
        <material name="drawer_beige" rgba=".4 .65 .4 1" shininess="1" reflectance="1" specular=".5"/>
        <material name="drawer_tan" rgba=	".545 .271 .075 1" shininess="1" reflectance="1" specular=".5"/>

        <mesh file="drawer.stl" name="drawer"/>
        <mesh file="drawercase.stl" name="drawercase"/>
        <mesh file="drawerhandle.stl" name="drawerhandle"/>
        <!--  -->

    </asset>
    <worldbody>
        <geom size="0 0 0.1" type="plane" material="matplane"/>
        <light pos="0 0 100" dir="0 0 -1" castshadow="false" diffuse="0.5 0.5 0.5"/>
        <body name="top" pos="0 0 0">
            <camera name="realsense-top" pos="0.13 0 2.02" euler="0 0 0" fovy="41"/>
        </body>
        <body name="front" pos="0 0 0">
            <camera name="realsense-front" pos="1.37 0 1.12" euler="0 1.571 -1.571" fovy="41"/>
        </body>
        <body name="side-1" pos="0 0 0">
            <camera name="realsense-side-1" pos="0.13 1 1.32" euler="-1.571 0 0" fovy="41"/>
        </body>
        <body name="side-2" pos="0 0 0">
            <camera name="realsense-side-2" pos="0.23 -1 1.02" euler="1.571 0 3.14" fovy="41"/>
        </body>

        <body childclass="drawer_base" pos="-0.17 0.5 0.82">
            <body name="drawercase_link" pos="0 0 0.084">
                <geom material="drawer_beige" mesh="drawercase"/>
                <geom class="drawer_col" pos="-0.11 0 0" size="0.008 0.1 0.084" type="box" mass=".05"/>
                <geom class="drawer_col" pos="0.11 0 0" size="0.008 0.1 0.084" type="box" mass=".05"/>
                <geom class="drawer_col" pos="0 0.092 -0.008" size="0.102 0.008 0.076" type="box" mass=".05"/>
                <geom class="drawer_col" pos="0 -0.008 -0.07" size="0.102 0.092 0.014" type="box" mass=".05"/>
                <geom class="drawer_col" pos="0 0 0.076" size="0.102 0.1 0.008" type="box" mass=".05"/>
                <body name="drawer_link" pos="0 -0.01 0.006">
                    <joint type="slide" range="-0.16 0" axis="0 1 0" name="goal_slidey" pos="0 0 0" damping="20"/>
    <!--                 <joint type="slide" range="-0.16 -0.05" axis="0 1 0" name="goal_slidey" pos="0 0 0" damping="5"/> -->
                    <geom material="drawer_beige" mesh="drawer"/>
                    <geom material="drawer_white" mesh="drawerhandle" pos="0 -0.114 0" name="handle"/>
    <!--                 <site name="handleStart" pos="0 -0.114 0.016" size="0.01" rgba="1 0 0 1"/> -->
                    <geom class="drawer_col" pos="0 -0.082 0.008" size="0.1 0.008 0.052" type="box" mass=".04" name="drawer_wall2"/>
                    <geom class="drawer_col" pos="0 0.082 0.008" size="0.1 0.008 0.052" type="box" mass=".04"/>
                    <geom class="drawer_col" pos="-0.092 0 0.008" size="0.008 0.074 0.052" type="box" mass=".04"/>
                    <geom class="drawer_col" pos="0.092 0 0.008" size="0.008 0.074 0.052" type="box" mass=".04"/>
                    <geom class="drawer_col" pos="0 0 -0.052" size="0.1 0.09 0.008" type="box" mass=".04"/>
                    <geom class="drawer_col" euler="1.571 0 0" pos="-0.05 -0.12 0.0" size="0.009 0.03" type="capsule" mass=".06"/>
                    <geom class="drawer_col" euler="0 1.57 0" pos="0 -0.15 0" size="0.009 0.05" type="capsule" mass=".06"/>
                    <geom class="drawer_col" euler="1.57 0 0" pos="0.05 -0.12 0" size="0.009 0.03" type="capsule" mass=".06"/>
                </body>
            </body>
        </body>
        <body name="Gen3_robot" pos="-0.07 0 0.82">
            <geom type="mesh" rgba="0.75294 0.75294 0.75294 1" mesh="base_link"/>
            <body name="shoulder_link" pos="0 0 0.15643" quat="-3.67321e-06 1 0 0">
                <joint name="robot0:joint_1" class="GEN3" pos="0 0 0" axis="0 0 1"/>
                <geom type="mesh" rgba="0.75294 0.75294 0.75294 1" mesh="shoulder_link"/>
                <body name="half_arm_1_link" pos="0 0.005375 -0.12838" quat="0.707105 0.707108 0 0">
                    <joint name="robot0:joint_2" class="GEN3" pos="0 0 0" axis="0 0 1" limited="true" range="-2.41 2.41"/>
                    <geom type="mesh" rgba="0.75294 0.75294 0.75294 1" mesh="half_arm_1_link"/>
                    <body name="half_arm_2_link" pos="0 -0.21038 -0.006375" quat="0.707105 -0.707108 0 0">
                        <joint name="robot0:joint_3" class="GEN3" pos="0 0 0" axis="0 0 1"/>
                        <geom type="mesh" rgba="0.75294 0.75294 0.75294 1" mesh="half_arm_2_link"/>
                        <body name="forearm_link" pos="0 0.006375 -0.21038" quat="0.707105 0.707108 0 0">
                            <joint name="robot0:joint_4" class="GEN3" pos="0 0 0" axis="0 0 1" limited="true" range="-2.66 2.66"/>
                            <geom type="mesh" rgba="0.75294 0.75294 0.75294 1" mesh="forearm_link"/>
                            <body name="spherical_wrist_1_link" pos="0 -0.20843 -0.006375" quat="0.707105 -0.707108 0 0">
                                <joint name="robot0:joint_5" class="GEN3" pos="0 0 0" axis="0 0 1"/>
                                <geom type="mesh" rgba="0.75294 0.75294 0.75294 1" mesh="spherical_wrist_1_link"/>
                                <body name="spherical_wrist_2_link" pos="0 0.00017505 -0.10593" quat="0.707105 0.707108 0 0">
                                    <joint name="robot0:joint_6" class="GEN3" pos="0 0 0" axis="0 0 1" limited="true" range="-2.23 2.23"/>
                                    <geom type="mesh" rgba="0.75294 0.75294 0.75294 1" mesh="spherical_wrist_2_link"/>
                                    <body name="bracelet_link" pos="0 -0.10593 -0.00017505" quat="0.707105 -0.707108 0 0">
                                        <joint name="robot0:joint_7" class="GEN3" pos="0 0 0" axis="0 0 1"/>
                                        <geom type="mesh" rgba="0.75294 0.75294 0.75294 1" mesh="bracelet_link"/>
                                        <geom pos="0 0 -0.061525" quat="-0.5 0.500398 -0.499602 -0.5" type="mesh" mesh="robotiq_85_base_link"/>
                                        <site name="robot0:0grip0" pos="0 0 -0.1" size="0.03" rgba="0 1 0 0"/>
                                        <site name="robot0:grip" pos="0 0 -0.21" size="0.01" rgba="0 1 0 0"/>
                                        <site name="gf1b_s" pos="-0.0126511 -1.01133e-05 -0.122955" size="0.002"/>
                                        <site name="gf2b_s" pos="0.0127489 1.01133e-05 -0.122935" size="0.002"/>
                                        <camera name="realsense" pos="0.0275 -0.066 -0.0585" fovy="41"/>
                                        <body name="gripper_finger1_knuckle_link" pos="-0.0305574 -2.43685e-05 -0.116454" quat="-0.500399 -0.499999 -0.500001 0.499601">
                                            <joint name="robot0:gripper_finger1_joint" class="2F-85" pos="0 0 0" axis="0 0 1" limited="true" range="0 0.804"/>
                                            <geom type="mesh" mesh="robotiq_85_knuckle_link"/>
                                            <body name="gripper_finger1_knuckle2_link" pos="0 0 0">
                                                <joint name="gripper_finger1_joint2" class="2F-85" pos="-0.00408552 -0.031486 0" axis="0 0 1" limited="true" range="0 0.804"/>
                                                <geom pos="-0.00408552 -0.031486 0" type="mesh" mesh="robotiq_85_finger_link"/>
                                                <body name="gripper_finger1_finger_tip_link" pos="0.05 -0.02 0">
                                                    <joint name="gripper_finger1_finger_tip_joint" class="2F-85" pos="-0.0066 -0.017245 0" axis="0 0 1" stiffness="50" range="0 0.804"/>
                                                    <geom type="mesh" condim="4" friction="0 0 0" solref="0.01 1" solimp="0.99 0.99 0.01 0.5 2" mesh="robotiq_85_finger_tip_link"/>
                                                    <geom name="tip_left_pivot" size="0.0018" pos="0.038 0.00925 0" condim="4" friction="1.2 0.005 0.0001" solref="0.01 1" solimp="0.99 0.99 0.01 0.5 2" rgba="0 0.7 0.1 1"/>
                                                    <geom name="tip_left_pivot_slip" size="0.0024" pos="0.038 0.00925 0" condim="4" friction="0.5 0.005 0.0001" solref="0.01 1" solimp="0.95 0.95 0.01 0.5 2" rgba="0 0.7 0.1 1"/>
                                                    <geom name="tip_left_rubber" size="0.019 0.001 0.011" pos="0.025 0.00925 0" type="box" condim="4" friction="1 0.08 0.0001" solref="0.01 1" solimp="0.98 0.98 0.01 0.5 6" rgba="1.5 0.7 0.1 1"/>
                                                    <body name="gripper_finger1_inner_knuckle_link" pos="-0.0430396 0.0375994 0">
                                                        <joint name="gripper_finger1_inner_knuckle_joint" class="2F-85" pos="0.0430396 -0.0375994 0" axis="0 0 1" limited="true" range="0 0.804"/>
                                                        <geom type="mesh" mesh="robotiq_85_inner_knuckle_link"/>
                                                        <site name="gf1a_s" pos="0 0 0" size="0.002" rgba="0.9 0.1 0.1 1"/>
                                                    </body>
                                                </body>
                                            </body>
                                        </body>
                                        <body name="gripper_finger2_knuckle_link" pos="0.0306448 2.43685e-05 -0.116405" quat="-0.5 0.500398 -0.499602 -0.5">
                                            <joint name="robot0:gripper_finger2_joint" class="2F-85" pos="0 0 0" axis="0 0 1" limited="true" range="0 0.804"/>
                                            <geom type="mesh" mesh="robotiq_85_knuckle_link"/>
                                            <body name="gripper_finger2_knuckle2_link" pos="0 0 0">
                                                <joint name="gripper_finger2_joint2" class="2F-85" pos="-0.00408552 -0.031486 0" axis="0 0 1" limited="true" range="0 0.804"/>
                                                <geom pos="-0.00408552 -0.031486 0" type="mesh" mesh="robotiq_85_finger_link"/>
                                                <body name="gripper_finger2_finger_tip_link" pos="0.05 -0.02 0">
                                                    <joint name="gripper_finger2_finger_tip_joint" class="2F-85" pos="-0.0066 -0.017245 0" axis="0 0 1" stiffness="50" range="0 0.804"/>
                                                    <geom type="mesh" condim="4" friction="0 0 0" solref="0.01 1" solimp="0.99 0.99 0.01 0.5 2" mesh="robotiq_85_finger_tip_link"/>
                                                    <geom name="tip_right_pivot" size="0.0018" pos="0.038 0.00925 0" condim="4" friction="1.2 0.01 0.0001" solref="0.01 1" solimp="0.99 0.99 0.01 0.5 2" rgba="0 0.7 0.1 1"/>
                                                    <geom name="tip_right_pivot_slip" size="0.0024" pos="0.038 0.00925 0" condim="4" friction="0.5 0.005 0.0001" solref="0.01 1" solimp="0.95 0.95 0.01 0.5 2" rgba="0 0.7 0.1 1"/>
                                                    <geom name="tip_right_rubber" size="0.019 0.001 0.011" pos="0.025 0.00925 0" type="box" condim="4" friction="1 0.08 0.0001" solref="0.01 1" solimp="0.98 0.98 0.01 0.5 6" rgba="1.5 0.7 0.1 1"/>
                                                    <body name="gripper_finger2_inner_knuckle_link" pos="-0.0430396 0.0375994 0">
                                                        <joint name="gripper_finger2_inner_knuckle_joint" class="2F-85" pos="0.0430396 -0.0375994 0" axis="0 0 1" limited="true" range="0 0.804"/>
                                                        <geom type="mesh" mesh="robotiq_85_inner_knuckle_link"/>
                                                        <site name="gf2a_s" pos="0 0 0" size="0.002" rgba="0.9 0.1 0.1 1"/>
                                                    </body>
                                                </body>
                                            </body>
                                        </body>
                                    </body>
                                </body>
                            </body>
                        </body>
                    </body>
                </body>
            </body>
        </body>
        <body name="Table" pos="0.475 0 0.8">
            <geom size="0.6 0.3 0.015" type="box" condim="4" friction="0.25 0.005 0.0001" solref="0.01 1" solimp="0.95 0.95 0.01 0.5 2" rgba="0.8 0.2 0.1 1"/>
            <geom size="0.0135 0.2" pos="-0.575 -0.275 -0.2" type="cylinder" rgba="0.8 0.2 0.1 1"/>
            <geom size="0.0135 0.2" pos="-0.575 0.275 -0.2" type="cylinder" rgba="0.8 0.2 0.1 1"/>
            <geom size="0.0135 0.2" pos="0.575 -0.275 -0.2" type="cylinder" rgba="0.8 0.2 0.1 1"/>
            <geom size="0.0135 0.2" pos="0.575 0.275 -0.2" type="cylinder" rgba="0.8 0.2 0.1 1"/>
            <geom name="spheret0" size="0.000161274" pos="0.0657688 -0.285357 0.015" condim="4" friction="0.25 0.005 0.0001" solref="0.01 1" solimp="0.95 0.95 0.01 0.5 2" rgba="1 1 1 1"/>
            <geom name="spheret1" size="0.000146776" pos="0.464746 0.0960393 0.015" condim="4" friction="0.25 0.005 0.0001" solref="0.01 1" solimp="0.95 0.95 0.01 0.5 2" rgba="1 1 1 1"/>
            <geom name="spheret2" size="0.00017469" pos="-0.496424 0.174359 0.015" condim="4" friction="0.25 0.005 0.0001" solref="0.01 1" solimp="0.95 0.95 0.01 0.5 2" rgba="1 1 1 1"/>
            <geom name="spheret3" size="9.93471e-05" pos="0.189616 0.0711343 0.015" condim="4" friction="0.25 0.005 0.0001" solref="0.01 1" solimp="0.95 0.95 0.01 0.5 2" rgba="1 1 1 1"/>
            <geom name="spheret4" size="0.00018197" pos="0.579507 0.00463367 0.015" condim="4" friction="0.25 0.005 0.0001" solref="0.01 1" solimp="0.95 0.95 0.01 0.5 2" rgba="1 1 1 1"/>
            <geom name="spheret5" size="0.000168294" pos="0.156998 0.195791 0.015" condim="4" friction="0.25 0.005 0.0001" solref="0.01 1" solimp="0.95 0.95 0.01 0.5 2" rgba="1 1 1 1"/>
            <geom name="spheret6" size="0.00011608" pos="-0.591187 -0.126367 0.015" condim="4" friction="0.25 0.005 0.0001" solref="0.01 1" solimp="0.95 0.95 0.01 0.5 2" rgba="1 1 1 1"/>
            <geom name="spheret7" size="0.000157237" pos="0.0823821 0.268346 0.015" condim="4" friction="0.25 0.005 0.0001" solref="0.01 1" solimp="0.95 0.95 0.01 0.5 2" rgba="1 1 1 1"/>
            <geom name="spheret8" size="0.000120652" pos="-0.141305 0.00166194 0.015" condim="4" friction="0.25 0.005 0.0001" solref="0.01 1" solimp="0.95 0.95 0.01 0.5 2" rgba="1 1 1 1"/>
            <geom name="spheret9" size="0.000104853" pos="0.134491 -0.134382 0.015" condim="4" friction="0.25 0.005 0.0001" solref="0.01 1" solimp="0.95 0.95 0.01 0.5 2" rgba="1 1 1 1"/>
            <geom name="spheret10" size="6.4659e-05" pos="-0.434194 -0.299419 0.015" condim="4" friction="0.25 0.005 0.0001" solref="0.01 1" solimp="0.95 0.95 0.01 0.5 2" rgba="1 1 1 1"/>
            <geom name="spheret11" size="0.000110009" pos="-0.339563 -0.0078653 0.015" condim="4" friction="0.25 0.005 0.0001" solref="0.01 1" solimp="0.95 0.95 0.01 0.5 2" rgba="1 1 1 1"/>
            <geom name="spheret12" size="0.000152961" pos="0.471766 0.108286 0.015" condim="4" friction="0.25 0.005 0.0001" solref="0.01 1" solimp="0.95 0.95 0.01 0.5 2" rgba="1 1 1 1"/>
            <geom name="spheret13" size="8.77399e-05" pos="0.411157 0.196437 0.015" condim="4" friction="0.25 0.005 0.0001" solref="0.01 1" solimp="0.95 0.95 0.01 0.5 2" rgba="1 1 1 1"/>
            <geom name="spheret14" size="6.44247e-05" pos="-0.590254 -0.0978682 0.015" condim="4" friction="0.25 0.005 0.0001" solref="0.01 1" solimp="0.95 0.95 0.01 0.5 2" rgba="1 1 1 1"/>
            <geom name="spheret15" size="7.7022e-05" pos="0.587752 0.227395 0.015" condim="4" friction="0.25 0.005 0.0001" solref="0.01 1" solimp="0.95 0.95 0.01 0.5 2" rgba="1 1 1 1"/>
            <geom name="spheret16" size="8.34693e-05" pos="-0.0828383 0.0958794 0.015" condim="4" friction="0.25 0.005 0.0001" solref="0.01 1" solimp="0.95 0.95 0.01 0.5 2" rgba="1 1 1 1"/>
            <geom name="spheret17" size="0.000189188" pos="-0.346853 0.164791 0.015" condim="4" friction="0.25 0.005 0.0001" solref="0.01 1" solimp="0.95 0.95 0.01 0.5 2" rgba="1 1 1 1"/>
            <geom name="spheret18" size="0.00016539" pos="0.0677559 -0.298668 0.015" condim="4" friction="0.25 0.005 0.0001" solref="0.01 1" solimp="0.95 0.95 0.01 0.5 2" rgba="1 1 1 1"/>
            <geom name="spheret19" size="0.000184423" pos="0.0356584 0.157315 0.015" condim="4" friction="0.25 0.005 0.0001" solref="0.01 1" solimp="0.95 0.95 0.01 0.5 2" rgba="1 1 1 1"/>
            <geom name="spheret20" size="5.31924e-05" pos="0.279766 0.220107 0.015" condim="4" friction="0.25 0.005 0.0001" solref="0.01 1" solimp="0.95 0.95 0.01 0.5 2" rgba="1 1 1 1"/>
            <geom name="spheret21" size="0.000144051" pos="0.58374 0.136086 0.015" condim="4" friction="0.25 0.005 0.0001" solref="0.01 1" solimp="0.95 0.95 0.01 0.5 2" rgba="1 1 1 1"/>
            <geom name="spheret22" size="0.000183741" pos="-0.480228 -0.0868238 0.015" condim="4" friction="0.25 0.005 0.0001" solref="0.01 1" solimp="0.95 0.95 0.01 0.5 2" rgba="1 1 1 1"/>
            <geom name="spheret23" size="8.22424e-05" pos="-0.343899 0.0732031 0.015" condim="4" friction="0.25 0.005 0.0001" solref="0.01 1" solimp="0.95 0.95 0.01 0.5 2" rgba="1 1 1 1"/>
            <geom name="spheret24" size="0.000134263" pos="-0.475456 -0.18981 0.015" condim="4" friction="0.25 0.005 0.0001" solref="0.01 1" solimp="0.95 0.95 0.01 0.5 2" rgba="1 1 1 1"/>
            <geom name="spheret25" size="8.56194e-05" pos="0.346688 -0.180348 0.015" condim="4" friction="0.25 0.005 0.0001" solref="0.01 1" solimp="0.95 0.95 0.01 0.5 2" rgba="1 1 1 1"/>
            <geom name="spheret26" size="8.90852e-05" pos="0.417252 0.132791 0.015" condim="4" friction="0.25 0.005 0.0001" solref="0.01 1" solimp="0.95 0.95 0.01 0.5 2" rgba="1 1 1 1"/>
            <geom name="spheret27" size="0.000169403" pos="0.481045 -0.207662 0.015" condim="4" friction="0.25 0.005 0.0001" solref="0.01 1" solimp="0.95 0.95 0.01 0.5 2" rgba="1 1 1 1"/>
            <geom name="spheret28" size="0.000155824" pos="-0.510816 0.179734 0.015" condim="4" friction="0.25 0.005 0.0001" solref="0.01 1" solimp="0.95 0.95 0.01 0.5 2" rgba="1 1 1 1"/>
            <geom name="spheret29" size="0.000197904" pos="-0.125941 -0.098736 0.015" condim="4" friction="0.25 0.005 0.0001" solref="0.01 1" solimp="0.95 0.95 0.01 0.5 2" rgba="1 1 1 1"/>
            <geom name="spheret30" size="0.000122282" pos="-0.545912 0.156889 0.015" condim="4" friction="0.25 0.005 0.0001" solref="0.01 1" solimp="0.95 0.95 0.01 0.5 2" rgba="1 1 1 1"/>
            <geom name="spheret31" size="0.000148123" pos="-0.217193 0.118613 0.015" condim="4" friction="0.25 0.005 0.0001" solref="0.01 1" solimp="0.95 0.95 0.01 0.5 2" rgba="1 1 1 1"/>
            <geom name="spheret32" size="0.000159078" pos="0.00420583 0.208703 0.015" condim="4" friction="0.25 0.005 0.0001" solref="0.01 1" solimp="0.95 0.95 0.01 0.5 2" rgba="1 1 1 1"/>
            <geom name="spheret33" size="0.000123592" pos="-0.496531 0.00434704 0.015" condim="4" friction="0.25 0.005 0.0001" solref="0.01 1" solimp="0.95 0.95 0.01 0.5 2" rgba="1 1 1 1"/>
            <geom name="spheret34" size="0.000177056" pos="-0.117984 0.233169 0.015" condim="4" friction="0.25 0.005 0.0001" solref="0.01 1" solimp="0.95 0.95 0.01 0.5 2" rgba="1 1 1 1"/>
            <geom name="spheret35" size="9.02778e-05" pos="0.157884 0.248204 0.015" condim="4" friction="0.25 0.005 0.0001" solref="0.01 1" solimp="0.95 0.95 0.01 0.5 2" rgba="1 1 1 1"/>
            <geom name="spheret36" size="0.000157915" pos="-0.474182 0.210779 0.015" condim="4" friction="0.25 0.005 0.0001" solref="0.01 1" solimp="0.95 0.95 0.01 0.5 2" rgba="1 1 1 1"/>
            <geom name="spheret37" size="0.000109788" pos="0.208207 0.133994 0.015" condim="4" friction="0.25 0.005 0.0001" solref="0.01 1" solimp="0.95 0.95 0.01 0.5 2" rgba="1 1 1 1"/>
            <geom name="spheret38" size="0.000104795" pos="-0.0160585 0.109241 0.015" condim="4" friction="0.25 0.005 0.0001" solref="0.01 1" solimp="0.95 0.95 0.01 0.5 2" rgba="1 1 1 1"/>
            <geom name="spheret39" size="0.000139346" pos="-0.295771 0.271767 0.015" condim="4" friction="0.25 0.005 0.0001" solref="0.01 1" solimp="0.95 0.95 0.01 0.5 2" rgba="1 1 1 1"/>
            <geom name="spheret40" size="0.000115173" pos="0.500662 0.114152 0.015" condim="4" friction="0.25 0.005 0.0001" solref="0.01 1" solimp="0.95 0.95 0.01 0.5 2" rgba="1 1 1 1"/>
            <geom name="spheret41" size="0.000143789" pos="-0.462595 -0.11865 0.015" condim="4" friction="0.25 0.005 0.0001" solref="0.01 1" solimp="0.95 0.95 0.01 0.5 2" rgba="1 1 1 1"/>
            <geom name="spheret42" size="0.000118445" pos="0.457482 -0.254023 0.015" condim="4" friction="0.25 0.005 0.0001" solref="0.01 1" solimp="0.95 0.95 0.01 0.5 2" rgba="1 1 1 1"/>
            <geom name="spheret43" size="8.07228e-05" pos="0.470186 0.0466219 0.015" condim="4" friction="0.25 0.005 0.0001" solref="0.01 1" solimp="0.95 0.95 0.01 0.5 2" rgba="1 1 1 1"/>
            <geom name="spheret44" size="0.000172443" pos="-0.482036 -0.126804 0.015" condim="4" friction="0.25 0.005 0.0001" solref="0.01 1" solimp="0.95 0.95 0.01 0.5 2" rgba="1 1 1 1"/>
            <geom name="spheret45" size="5.8287e-05" pos="0.10569 -0.12528 0.015" condim="4" friction="0.25 0.005 0.0001" solref="0.01 1" solimp="0.95 0.95 0.01 0.5 2" rgba="1 1 1 1"/>
            <geom name="spheret46" size="0.000151209" pos="0.173357 -0.119862 0.015" condim="4" friction="0.25 0.005 0.0001" solref="0.01 1" solimp="0.95 0.95 0.01 0.5 2" rgba="1 1 1 1"/>
            <geom name="spheret47" size="0.000163678" pos="0.579669 -0.0724445 0.015" condim="4" friction="0.25 0.005 0.0001" solref="0.01 1" solimp="0.95 0.95 0.01 0.5 2" rgba="1 1 1 1"/>
            <geom name="spheret48" size="0.00018377" pos="0.0489625 -0.0278564 0.015" condim="4" friction="0.25 0.005 0.0001" solref="0.01 1" solimp="0.95 0.95 0.01 0.5 2" rgba="1 1 1 1"/>
            <geom name="spheret49" size="0.000166675" pos="0.17783 0.0461231 0.015" condim="4" friction="0.25 0.005 0.0001" solref="0.01 1" solimp="0.95 0.95 0.01 0.5 2" rgba="1 1 1 1"/>
            <geom name="spheret50" size="5.56036e-05" pos="0.27453 -0.166604 0.015" condim="4" friction="0.25 0.005 0.0001" solref="0.01 1" solimp="0.95 0.95 0.01 0.5 2" rgba="1 1 1 1"/>
            <geom name="spheret51" size="0.000133155" pos="0.315192 0.0801921 0.015" condim="4" friction="0.25 0.005 0.0001" solref="0.01 1" solimp="0.95 0.95 0.01 0.5 2" rgba="1 1 1 1"/>
            <geom name="spheret52" size="9.70095e-05" pos="0.383207 0.145148 0.015" condim="4" friction="0.25 0.005 0.0001" solref="0.01 1" solimp="0.95 0.95 0.01 0.5 2" rgba="1 1 1 1"/>
            <geom name="spheret53" size="0.000112865" pos="0.436042 -0.060325 0.015" condim="4" friction="0.25 0.005 0.0001" solref="0.01 1" solimp="0.95 0.95 0.01 0.5 2" rgba="1 1 1 1"/>
            <geom name="spheret54" size="0.000124894" pos="0.420731 -0.13674 0.015" condim="4" friction="0.25 0.005 0.0001" solref="0.01 1" solimp="0.95 0.95 0.01 0.5 2" rgba="1 1 1 1"/>
            <geom name="spheret55" size="7.09267e-05" pos="0.441488 0.0468498 0.015" condim="4" friction="0.25 0.005 0.0001" solref="0.01 1" solimp="0.95 0.95 0.01 0.5 2" rgba="1 1 1 1"/>
            <geom name="spheret56" size="9.45492e-05" pos="-0.535272 0.0933327 0.015" condim="4" friction="0.25 0.005 0.0001" solref="0.01 1" solimp="0.95 0.95 0.01 0.5 2" rgba="1 1 1 1"/>
            <geom name="spheret57" size="0.000184761" pos="-0.448493 -0.208359 0.015" condim="4" friction="0.25 0.005 0.0001" solref="0.01 1" solimp="0.95 0.95 0.01 0.5 2" rgba="1 1 1 1"/>
            <geom name="spheret58" size="6.1768e-05" pos="0.110266 0.0161921 0.015" condim="4" friction="0.25 0.005 0.0001" solref="0.01 1" solimp="0.95 0.95 0.01 0.5 2" rgba="1 1 1 1"/>
            <geom name="spheret59" size="0.000176198" pos="-0.119266 -0.241182 0.015" condim="4" friction="0.25 0.005 0.0001" solref="0.01 1" solimp="0.95 0.95 0.01 0.5 2" rgba="1 1 1 1"/>
            <geom name="spheret60" size="0.000167843" pos="-0.419622 -0.211429 0.015" condim="4" friction="0.25 0.005 0.0001" solref="0.01 1" solimp="0.95 0.95 0.01 0.5 2" rgba="1 1 1 1"/>
            <geom name="spheret61" size="0.000167873" pos="0.431704 0.125827 0.015" condim="4" friction="0.25 0.005 0.0001" solref="0.01 1" solimp="0.95 0.95 0.01 0.5 2" rgba="1 1 1 1"/>
            <geom name="spheret62" size="9.77953e-05" pos="0.550369 -0.263813 0.015" condim="4" friction="0.25 0.005 0.0001" solref="0.01 1" solimp="0.95 0.95 0.01 0.5 2" rgba="1 1 1 1"/>
            <geom name="spheret63" size="0.000192062" pos="0.267364 -0.233407 0.015" condim="4" friction="0.25 0.005 0.0001" solref="0.01 1" solimp="0.95 0.95 0.01 0.5 2" rgba="1 1 1 1"/>
            <geom name="spheret64" size="9.54081e-05" pos="-0.233841 -0.200167 0.015" condim="4" friction="0.25 0.005 0.0001" solref="0.01 1" solimp="0.95 0.95 0.01 0.5 2" rgba="1 1 1 1"/>
            <geom name="spheret65" size="0.000157351" pos="0.132463 0.088702 0.015" condim="4" friction="0.25 0.005 0.0001" solref="0.01 1" solimp="0.95 0.95 0.01 0.5 2" rgba="1 1 1 1"/>
            <geom name="spheret66" size="5.4535e-05" pos="0.184374 -0.198789 0.015" condim="4" friction="0.25 0.005 0.0001" solref="0.01 1" solimp="0.95 0.95 0.01 0.5 2" rgba="1 1 1 1"/>
            <geom name="spheret67" size="9.20946e-05" pos="0.35062 0.109946 0.015" condim="4" friction="0.25 0.005 0.0001" solref="0.01 1" solimp="0.95 0.95 0.01 0.5 2" rgba="1 1 1 1"/>
            <geom name="spheret68" size="7.09152e-05" pos="0.195623 0.187668 0.015" condim="4" friction="0.25 0.005 0.0001" solref="0.01 1" solimp="0.95 0.95 0.01 0.5 2" rgba="1 1 1 1"/>
            <geom name="spheret69" size="0.00012272" pos="0.0756816 -0.000980668 0.015" condim="4" friction="0.25 0.005 0.0001" solref="0.01 1" solimp="0.95 0.95 0.01 0.5 2" rgba="1 1 1 1"/>
            <geom name="spheret70" size="0.000127433" pos="-0.293901 0.0719917 0.015" condim="4" friction="0.25 0.005 0.0001" solref="0.01 1" solimp="0.95 0.95 0.01 0.5 2" rgba="1 1 1 1"/>
            <geom name="spheret71" size="6.76256e-05" pos="-0.544517 -0.200076 0.015" condim="4" friction="0.25 0.005 0.0001" solref="0.01 1" solimp="0.95 0.95 0.01 0.5 2" rgba="1 1 1 1"/>
            <geom name="spheret72" size="0.000103868" pos="0.385438 0.000490168 0.015" condim="4" friction="0.25 0.005 0.0001" solref="0.01 1" solimp="0.95 0.95 0.01 0.5 2" rgba="1 1 1 1"/>
            <geom name="spheret73" size="0.000184365" pos="-0.230984 0.112476 0.015" condim="4" friction="0.25 0.005 0.0001" solref="0.01 1" solimp="0.95 0.95 0.01 0.5 2" rgba="1 1 1 1"/>
            <geom name="spheret74" size="0.000163384" pos="0.499176 0.242645 0.015" condim="4" friction="0.25 0.005 0.0001" solref="0.01 1" solimp="0.95 0.95 0.01 0.5 2" rgba="1 1 1 1"/>
            <geom name="spheret75" size="5.0172e-05" pos="0.154639 0.0905804 0.015" condim="4" friction="0.25 0.005 0.0001" solref="0.01 1" solimp="0.95 0.95 0.01 0.5 2" rgba="1 1 1 1"/>
            <geom name="spheret76" size="0.000142403" pos="0.22979 0.0509227 0.015" condim="4" friction="0.25 0.005 0.0001" solref="0.01 1" solimp="0.95 0.95 0.01 0.5 2" rgba="1 1 1 1"/>
            <geom name="spheret77" size="8.24361e-05" pos="-0.260077 0.142967 0.015" condim="4" friction="0.25 0.005 0.0001" solref="0.01 1" solimp="0.95 0.95 0.01 0.5 2" rgba="1 1 1 1"/>
            <geom name="spheret78" size="0.000116025" pos="-0.300837 0.0273448 0.015" condim="4" friction="0.25 0.005 0.0001" solref="0.01 1" solimp="0.95 0.95 0.01 0.5 2" rgba="1 1 1 1"/>
            <geom name="spheret79" size="7.23694e-05" pos="0.0800585 0.0293176 0.015" condim="4" friction="0.25 0.005 0.0001" solref="0.01 1" solimp="0.95 0.95 0.01 0.5 2" rgba="1 1 1 1"/>
            <geom name="spheret80" size="0.000178708" pos="-0.523514 -0.128574 0.015" condim="4" friction="0.25 0.005 0.0001" solref="0.01 1" solimp="0.95 0.95 0.01 0.5 2" rgba="1 1 1 1"/>
            <geom name="spheret81" size="0.00015244" pos="-0.461617 -0.0945331 0.015" condim="4" friction="0.25 0.005 0.0001" solref="0.01 1" solimp="0.95 0.95 0.01 0.5 2" rgba="1 1 1 1"/>
            <geom name="spheret82" size="0.000159096" pos="-0.442858 0.232778 0.015" condim="4" friction="0.25 0.005 0.0001" solref="0.01 1" solimp="0.95 0.95 0.01 0.5 2" rgba="1 1 1 1"/>
            <geom name="spheret83" size="0.0001216" pos="-0.553206 0.237235 0.015" condim="4" friction="0.25 0.005 0.0001" solref="0.01 1" solimp="0.95 0.95 0.01 0.5 2" rgba="1 1 1 1"/>
            <geom name="spheret84" size="0.000138281" pos="-0.256667 -0.228756 0.015" condim="4" friction="0.25 0.005 0.0001" solref="0.01 1" solimp="0.95 0.95 0.01 0.5 2" rgba="1 1 1 1"/>
            <geom name="spheret85" size="0.000165291" pos="-0.555647 0.164295 0.015" condim="4" friction="0.25 0.005 0.0001" solref="0.01 1" solimp="0.95 0.95 0.01 0.5 2" rgba="1 1 1 1"/>
            <geom name="spheret86" size="0.000179328" pos="0.0154575 -0.0741255 0.015" condim="4" friction="0.25 0.005 0.0001" solref="0.01 1" solimp="0.95 0.95 0.01 0.5 2" rgba="1 1 1 1"/>
            <geom name="spheret87" size="8.10819e-05" pos="0.251967 0.249284 0.015" condim="4" friction="0.25 0.005 0.0001" solref="0.01 1" solimp="0.95 0.95 0.01 0.5 2" rgba="1 1 1 1"/>
            <geom name="spheret88" size="6.25559e-05" pos="0.400107 0.0280638 0.015" condim="4" friction="0.25 0.005 0.0001" solref="0.01 1" solimp="0.95 0.95 0.01 0.5 2" rgba="1 1 1 1"/>
            <geom name="spheret89" size="0.000190247" pos="-0.396415 -0.180735 0.015" condim="4" friction="0.25 0.005 0.0001" solref="0.01 1" solimp="0.95 0.95 0.01 0.5 2" rgba="1 1 1 1"/>
            <geom name="spheret90" size="0.000165527" pos="0.486079 -0.15068 0.015" condim="4" friction="0.25 0.005 0.0001" solref="0.01 1" solimp="0.95 0.95 0.01 0.5 2" rgba="1 1 1 1"/>
            <geom name="spheret91" size="7.05227e-05" pos="-0.0566122 0.0587162 0.015" condim="4" friction="0.25 0.005 0.0001" solref="0.01 1" solimp="0.95 0.95 0.01 0.5 2" rgba="1 1 1 1"/>
            <geom name="spheret92" size="7.36799e-05" pos="0.338899 -0.161051 0.015" condim="4" friction="0.25 0.005 0.0001" solref="0.01 1" solimp="0.95 0.95 0.01 0.5 2" rgba="1 1 1 1"/>
            <geom name="spheret93" size="5.12696e-05" pos="0.186247 -0.278995 0.015" condim="4" friction="0.25 0.005 0.0001" solref="0.01 1" solimp="0.95 0.95 0.01 0.5 2" rgba="1 1 1 1"/>
            <geom name="spheret94" size="5.71975e-05" pos="-0.539515 -0.0505125 0.015" condim="4" friction="0.25 0.005 0.0001" solref="0.01 1" solimp="0.95 0.95 0.01 0.5 2" rgba="1 1 1 1"/>
            <geom name="spheret95" size="0.000187064" pos="0.331494 -0.0922231 0.015" condim="4" friction="0.25 0.005 0.0001" solref="0.01 1" solimp="0.95 0.95 0.01 0.5 2" rgba="1 1 1 1"/>
            <geom name="spheret96" size="0.000162691" pos="0.32832 0.0325593 0.015" condim="4" friction="0.25 0.005 0.0001" solref="0.01 1" solimp="0.95 0.95 0.01 0.5 2" rgba="1 1 1 1"/>
            <geom name="spheret97" size="0.000115586" pos="0.363175 -0.0395582 0.015" condim="4" friction="0.25 0.005 0.0001" solref="0.01 1" solimp="0.95 0.95 0.01 0.5 2" rgba="1 1 1 1"/>
            <geom name="spheret98" size="0.000193474" pos="0.250797 0.259374 0.015" condim="4" friction="0.25 0.005 0.0001" solref="0.01 1" solimp="0.95 0.95 0.01 0.5 2" rgba="1 1 1 1"/>
            <geom name="spheret99" size="0.000126766" pos="-0.119113 0.156056 0.015" condim="4" friction="0.25 0.005 0.0001" solref="0.01 1" solimp="0.95 0.95 0.01 0.5 2" rgba="1 1 1 1"/>
            <site name="target0" pos="-0.1 -0.25 0.015" size="0.02 0.0001" type="cylinder" rgba="0 1 0 1"/>
        </body>
        <body name="ConSurf" pos="0.45 0 0.84">
            <joint name="object0:joint_x" pos="0 0 0" axis="1 0 0" type="slide" damping="0.01"/>
            <joint name="object0:joint_y" pos="0 0 0" axis="0 1 0" type="slide" damping="0.01"/>
            <joint name="object0:joint_z" pos="0 0 0" axis="0 0 1" type="slide" damping="0.01"/>
            <joint name="object0:joint_r" pos="0 0 0" axis="1 0 0" damping="0.01"/>
            <joint name="object0:joint_p" pos="0 0 0" axis="0 1 0" damping="0.01"/>
            <joint name="object0:joint_yw" pos="0 0 0" axis="0 0 1" damping="0.01"/>
            <geom name="ConSurf" size="0.035 0.015 0.025" type="box" priority="2" friction="0.45 0.005 0.0001" solref="0.01 1" solimp="0.95 0.95 0.01 0.5 2" rgba="0.999 0.999 0.999 1"/>
            <site name="object0" pos="0 0 -0.025" size="0.0001 0.0001" type="cylinder" rgba="0 1 0 1"/>
        </body>
    </worldbody>
    <equality>
        <tendon tendon1="gf1_t" polycoef="0 1 0 0 0" solref="0.01 1" solimp="0.99 0.99 0.001 0.5 2"/>
        <tendon tendon1="gf2_t" polycoef="0 1 0 0 0" solref="0.01 1" solimp="0.99 0.99 0.001 0.5 2"/>
    </equality>
    <tendon>
        <spatial name="gf1_t" stiffness="10" damping="0.2" width="2e-05" rgba="0.9 0.9 0.9 1">
            <site site="gf1a_s"/>
            <site site="gf1b_s"/>
        </spatial>
        <spatial name="gf2_t" stiffness="10" damping="0.2" width="2e-05" rgba="0.9 0.9 0.9 1">
            <site site="gf2a_s"/>
            <site site="gf2b_s"/>
        </spatial>
    </tendon>
    <actuator>
        <general name="Joint1" joint="robot0:joint_1" ctrllimited="true" ctrlrange="-39 39" gear="3 0 0 0 0 0"/>
        <general name="Joint2" joint="robot0:joint_2" ctrllimited="true" ctrlrange="-39 39" gear="3 0 0 0 0 0"/>
        <general name="Joint3" joint="robot0:joint_3" ctrllimited="true" ctrlrange="-39 39" gear="3 0 0 0 0 0"/>
        <general name="Joint4" joint="robot0:joint_4" ctrllimited="true" ctrlrange="-39 39" gear="3 0 0 0 0 0"/>
        <general name="Joint5" joint="robot0:joint_5" ctrllimited="true" ctrlrange="-19 19" gear="3 0 0 0 0 0"/>
        <general name="Joint6" joint="robot0:joint_6" ctrllimited="true" ctrlrange="-19 19" gear="3 0 0 0 0 0"/>
        <general name="Joint7" joint="robot0:joint_7" ctrllimited="true" ctrlrange="-19 19" gear="3 0 0 0 0 0"/>
        <general name="JointGL" joint="robot0:gripper_finger1_joint" ctrllimited="true" ctrlrange="0 1.5" forcerange="0 5" biastype="affine" gainprm="80 0 0 0 0 0 0 0 0 0" biasprm="0 -80 0 0 0 0 0 0 0 0"/>
        <general name="JointGR" joint="robot0:gripper_finger2_joint" ctrllimited="true" ctrlrange="0 1.5" forcerange="0 5" biastype="affine" gainprm="80 0 0 0 0 0 0 0 0 0" biasprm="0 -80 0 0 0 0 0 0 0 0"/>
    </actuator>
    <!-- <keyframe>
        <key time="27.40599999999569" qpos="-0.07338055684478571 0.18530959070405084 -3.0538240316206506 -1.9300998209447195 -0.01738254395532628 -1.0446910130234817 1.590320736053424 -0.0012384396993817002 -0.0011142029702208788 -0.0011682343686317707 0.005208317775120642 -0.0012387769075628593 -0.001114334922530629 -0.0011600604305032488 0.005191867245129356 0.0 0.0 -2.4524999999997703e-05 0.0 0.0 0.0" qvel="1.171719795092661e-05 3.279284538257505e-07 -1.2810052553215048e-05 4.3367767933013723e-07 5.645341956605071e-07 -1.471480538857885e-07 -1.3034927458208762e-07 -4.223195041874307e-12 -4.251294472862627e-12 1.527118307350575e-11 -1.2287183221436282e-11 4.207064719540492e-12 4.278950632635882e-12 -1.451818411274012e-11 1.2725848441392307e-11 0.0 0.0 3.1798185050280446e-16 0.0 0.0 0.0"/>
    </keyframe> -->
</mujoco>